Workbook

Sheet Instrucciones
B38: Nota: Valor de la Ponderación / Peso Objetivo (%): | P38: Nota: Valor de la Ponderación / Peso Objetivo (%):
B39:  El rango de los objetivos está entre 10 y 40. | P39:  El rango de los objetivos está entre 10 y 40.
B40:   Total porcentaje = 100% | P40:   Total porcentaje = 100%
B77: Nota: Valor de la Ponderación / Peso Objetivo (%):
B78:  El rango de los objetivos está entre 10 y 40.
B79:   Total porcentaje = 100%
T81: Antes de guardar como PDF o imprimir, filtrar y desmarcar las vacías.

Sheet RESULTADOS_OBJETIVOS
A1: Periodo Evaluado | C1: Programa | D1: =IF(ISBLANK('Supervis@r'!$C$2),"",'Supervis@r'!$C$2) -> ENCARGADOS Y CAPATACES
A2: =CONCATENATE('Supervis@r'!$I$2,"-",'Supervis@r'!$J$2) -> 2025-2026 | C2: Supervisor/a | D2: =IF(ISBLANK('Supervis@r'!$C$3),"",CONCATENATE('Supervis@r'!$C$3," ",'Supervis@r'!$C$4,", ",'Supervis@r'!$C$5)) -> JEFE JEFE, JOSE
A4: Ir a la hoja de cálculo número | B4: DNI | C4: Apellido1 | D4: Apellido2 | E4: Nombre | F4: Puntuación aportada (0 - 100) | G4: ROL | H4: BOLSA DEL PROGRAMA (en caso de participación)
A5: 1 | B5: =IF(ISBLANK('Supervis@r'!$G$7),"",'Supervis@r'!$G$7) -> 23456789B | C5: =IF(ISBLANK('Supervis@r'!$C$3),"",'Supervis@r'!$C$3) -> JEFE | D5: =IF(ISBLANK('Supervis@r'!$C$4),"",'Supervis@r'!$C$4) -> JEFE | E5: =IF(ISBLANK('Supervis@r'!$C$5),"",'Supervis@r'!$C$5) -> JOSE | F5: =IF(ISBLANK('Supervis@r'!$G$7),"",'Supervis@r'!$J$19) -> 100 | G5: =IF(B5="","","Supervisor/a") -> Supervisor/a | H5: =IF(B5="","",IF(F5>=0,IF(F5<70,"NO RECIBE BOLSA","RECIBE BOLSA"),"")) -> RECIBE BOLSA
A6: 2 | B6: =IF(ISBLANK('Supervis@r_Int1'!$G$5),"",'Supervis@r_Int1'!$G$5) -> 23456780D | C6: =IF(ISBLANK('Supervis@r_Int1'!$C$6),"",'Supervis@r_Int1'!$C$6) -> ADMIN | D6: =IF(ISBLANK('Supervis@r_Int1'!$C$7),"",'Supervis@r_Int1'!$C$7) -> ADMIN | E6: =IF(ISBLANK('Supervis@r_Int1'!$C$8),"",'Supervis@r_Int1'!$C$8) -> ANTONIO | F6: =IF(ISBLANK('Supervis@r_Int1'!$G$5),"",'Supervis@r_Int1'!$J$17) -> 100 | G6: =IF(B6="","","Supervisor/a Intermedio") -> Supervisor/a Intermedio | H6: =IF(B6="","",IF(F6>=0,IF(F6<70,"NO RECIBE BOLSA","RECIBE BOLSA"),"")) -> RECIBE BOLSA
A7: 3 | B7: =IF(ISBLANK('Supervis@r_Int2'!$G$5),"",'Supervis@r_Int2'!$G$5) -> 87654321F | C7: =IF(ISBLANK('Supervis@r_Int2'!$C$6),"",'Supervis@r_Int2'!$C$6) -> MECANICO | D7: =IF(ISBLANK('Supervis@r_Int2'!$C$7),"",'Supervis@r_Int2'!$C$7) -> MECANICO | E7: =IF(ISBLANK('Supervis@r_Int2'!$C$8),"",'Supervis@r_Int2'!$C$8) -> EDUARDO | F7: =IF(ISBLANK('Supervis@r_Int2'!$G$5),"",'Supervis@r_Int2'!$J$17) -> 100 | G7: =IF(B7="","","Supervisor/a Intermedio") -> Supervisor/a Intermedio | H7: =IF(B7="","",IF(F7>=0,IF(F7<70,"NO RECIBE BOLSA","RECIBE BOLSA"),"")) -> RECIBE BOLSA
A8: 4 | B8: =IF(ISBLANK('Supervis@r_Int3'!$G$5),"",'Supervis@r_Int3'!$G$5) | C8: =IF(ISBLANK('Supervis@r_Int3'!$C$6),"",'Supervis@r_Int3'!$C$6) | D8: =IF(ISBLANK('Supervis@r_Int3'!$C$7),"",'Supervis@r_Int3'!$C$7) | E8: =IF(ISBLANK('Supervis@r_Int3'!$C$8),"",'Supervis@r_Int3'!$C$8) | F8: =IF(ISBLANK('Supervis@r_Int3'!$G$5),"",'Supervis@r_Int3'!$J$17) | G8: =IF(B8="","","Supervisor/a Intermedio") | H8: =IF(B8="","",IF(F8>=0,IF(F8<70,"NO RECIBE BOLSA","RECIBE BOLSA"),""))
A9: 5 | B9: =IF(ISBLANK('Supervis@r_Int4'!$G$5),"",'Supervis@r_Int4'!$G$5) | C9: =IF(ISBLANK('Supervis@r_Int4'!$C$6),"",'Supervis@r_Int4'!$C$6) | D9: =IF(ISBLANK('Supervis@r_Int4'!$C$7),"",'Supervis@r_Int4'!$C$7) | E9: =IF(ISBLANK('Supervis@r_Int4'!$C$8),"",'Supervis@r_Int4'!$C$8) | F9: =IF(ISBLANK('Supervis@r_Int4'!$G$5),"",'Supervis@r_Int4'!$J$17) | G9: =IF(B9="","","Supervisor/a Intermedio") | H9: =IF(B9="","",IF(F9>=0,IF(F9<70,"NO RECIBE BOLSA","RECIBE BOLSA"),""))
A10: 6 | B10: =IF(ISBLANK('Supervis@r_Int5'!$G$5),"",'Supervis@r_Int5'!$G$5) | C10: =IF(ISBLANK('Supervis@r_Int5'!$C$6),"",'Supervis@r_Int5'!$C$6) | D10: =IF(ISBLANK('Supervis@r_Int5'!$C$7),"",'Supervis@r_Int5'!$C$7) | E10: =IF(ISBLANK('Supervis@r_Int5'!$C$8),"",'Supervis@r_Int5'!$C$8) | F10: =IF(ISBLANK('Supervis@r_Int5'!$G$5),"",'Supervis@r_Int5'!$J$17) | G10: =IF(B10="","","Supervisor/a Intermedio") | H10: =IF(B10="","",IF(F10>=0,IF(F10<70,"NO RECIBE BOLSA","RECIBE BOLSA"),""))
A11: 7 | B11: =IF(ISBLANK('Supervis@r_Int6'!$G$5),"",'Supervis@r_Int6'!$G$5) | C11: =IF(ISBLANK('Supervis@r_Int6'!$C$6),"",'Supervis@r_Int6'!$C$6) | D11: =IF(ISBLANK('Supervis@r_Int6'!$C$7),"",'Supervis@r_Int6'!$C$7) | E11: =IF(ISBLANK('Supervis@r_Int6'!$C$8),"",'Supervis@r_Int6'!$C$8) | F11: =IF(ISBLANK('Supervis@r_Int6'!$G$5),"",'Supervis@r_Int6'!$J$17) | G11: =IF(B11="","","Supervisor/a Intermedio") | H11: =IF(B11="","",IF(F11>=0,IF(F11<70,"NO RECIBE BOLSA","RECIBE BOLSA"),""))
A12: 8 | B12: =IF(ISBLANK('Supervis@r_Int7'!$G$5),"",'Supervis@r_Int7'!$G$5) | C12: =IF(ISBLANK('Supervis@r_Int7'!$C$6),"",'Supervis@r_Int7'!$C$6) | D12: =IF(ISBLANK('Supervis@r_Int7'!$C$7),"",'Supervis@r_Int7'!$C$7) | E12: =IF(ISBLANK('Supervis@r_Int7'!$C$8),"",'Supervis@r_Int7'!$C$8) | F12: =IF(ISBLANK('Supervis@r_Int7'!$G$5),"",'Supervis@r_Int7'!$J$17) | G12: =IF(B12="","","Supervisor/a Intermedio") | H12: =IF(B12="","",IF(F12>=0,IF(F12<70,"NO RECIBE BOLSA","RECIBE BOLSA"),""))
A13: 9 | B13: =IF(ISBLANK('Supervis@r_Int8'!$G$5),"",'Supervis@r_Int8'!$G$5) | C13: =IF(ISBLANK('Supervis@r_Int8'!$C$6),"",'Supervis@r_Int8'!$C$6) | D13: =IF(ISBLANK('Supervis@r_Int8'!$C$7),"",'Supervis@r_Int8'!$C$7) | E13: =IF(ISBLANK('Supervis@r_Int8'!$C$8),"",'Supervis@r_Int8'!$C$8) | F13: =IF(ISBLANK('Supervis@r_Int8'!$G$5),"",'Supervis@r_Int8'!$J$17) | G13: =IF(B13="","","Supervisor/a Intermedio") | H13: =IF(B13="","",IF(F13>=0,IF(F13<70,"NO RECIBE BOLSA","RECIBE BOLSA"),""))
A14: 10 | B14: =IF(ISBLANK('Supervis@r_Int9'!$G$5),"",'Supervis@r_Int9'!$G$5) | C14: =IF(ISBLANK('Supervis@r_Int9'!$C$6),"",'Supervis@r_Int9'!$C$6) | D14: =IF(ISBLANK('Supervis@r_Int9'!$C$7),"",'Supervis@r_Int9'!$C$7) | E14: =IF(ISBLANK('Supervis@r_Int9'!$C$8),"",'Supervis@r_Int9'!$C$8) | F14: =IF(ISBLANK('Supervis@r_Int9'!$G$5),"",'Supervis@r_Int9'!$J$17) | G14: =IF(B14="","","Supervisor/a Intermedio") | H14: =IF(B14="","",IF(F14>=0,IF(F14<70,"NO RECIBE BOLSA","RECIBE BOLSA"),""))
A15: 11 | B15: =IF(ISBLANK('Supervis@r_Int10'!$G$5),"",'Supervis@r_Int10'!$G$5) | C15: =IF(ISBLANK('Supervis@r_Int10'!$C$6),"",'Supervis@r_Int10'!$C$6) | D15: =IF(ISBLANK('Supervis@r_Int10'!$C$7),"",'Supervis@r_Int10'!$C$7) | E15: =IF(ISBLANK('Supervis@r_Int10'!$C$8),"",'Supervis@r_Int10'!$C$8) | F15: =IF(ISBLANK('Supervis@r_Int10'!$G$5),"",'Supervis@r_Int10'!$J$17) | G15: =IF(B15="","","Supervisor/a Intermedio") | H15: =IF(B15="","",IF(F15>=0,IF(F15<70,"NO RECIBE BOLSA","RECIBE BOLSA"),""))
A16: 12 | B16: =IF(ISBLANK('Supervis@r_Int11'!$G$5),"",'Supervis@r_Int11'!$G$5) | C16: =IF(ISBLANK('Supervis@r_Int11'!$C$6),"",'Supervis@r_Int11'!$C$6) | D16: =IF(ISBLANK('Supervis@r_Int11'!$C$7),"",'Supervis@r_Int11'!$C$7) | E16: =IF(ISBLANK('Supervis@r_Int11'!$C$8),"",'Supervis@r_Int11'!$C$8) | F16: =IF(ISBLANK('Supervis@r_Int11'!$G$5),"",'Supervis@r_Int11'!$J$17) | G16: =IF(B16="","","Supervisor/a Intermedio") | H16: =IF(B16="","",IF(F16>=0,IF(F16<70,"NO RECIBE BOLSA","RECIBE BOLSA"),""))
A17: 13 | B17: =IF(ISBLANK('Supervis@r_Int12'!$G$5),"",'Supervis@r_Int12'!$G$5) | C17: =IF(ISBLANK('Supervis@r_Int12'!$C$6),"",'Supervis@r_Int12'!$C$6) | D17: =IF(ISBLANK('Supervis@r_Int12'!$C$7),"",'Supervis@r_Int12'!$C$7) | E17: =IF(ISBLANK('Supervis@r_Int12'!$C$8),"",'Supervis@r_Int12'!$C$8) | F17: =IF(ISBLANK('Supervis@r_Int12'!$G$5),"",'Supervis@r_Int12'!$J$17) | G17: =IF(B17="","","Supervisor/a Intermedio") | H17: =IF(B17="","",IF(F17>=0,IF(F17<70,"NO RECIBE BOLSA","RECIBE BOLSA"),""))

Sheet Supervis@r
A1: Unidad Organizativa | C1: SERVICIOS OPERATIVOS | I1: Periodo Evaluado
A2: Programa | C2: ENCARGADOS Y CAPATACES | I2: 2025 | J2: =$I$2+1 -> 2026
A3: Apellido1 Supervisor/a | C3: JEFE
A4: Apellido2 Supervisor/a | C4: JEFE
A5: Nombre Supervisor/a | C5: JOSE
A7: Puesto evaluado | C7: ENCARGADO GENERAL | F7: DNI | G7: 23456789B | H7: ROL | I7: Supervisor/a
A8: Apellido1 | C8: =IF(C3="","",C3) -> JEFE
A9: Apellido2 | C9: =IF(C4="","",C4) -> JEFE
A10: Nombre | C10: =IF(C5="","",C5) -> JOSE
A12: ID | B12: Objetivo (Descripción) | C12: Tipo Objetivo (Individual/Colectivo) | D12: Ponderación / Peso Objetivo (%) | E12: Categoría (Número/Porcentaje) | F12: Umbral (nivel de consecución esperado) | G12: Superación (Alza/Baja) | H12: Resultado Alcanzado | I12: Superación Umbral (SÍ/NO) | J12: Puntuación aportada (0 - 100)
A13: =IF(B13="","",COUNTA($B$13:B13)) -> 1 | B13: Realizar al menos 15 horas de formación "no obligatoria" en el periodo a evaluar, con las consideraciones recogidas en el Reglamento de ED | C13: Individual | D13: 0.2 | E13: Número | F13: 15 | G13: Alza | H13: 15 | I13: =IFERROR(IF(OR(A13="",F13=""),"",IF(AND(G13<>"Alza",G13<>"Baja"),"",IF(G13="Alza",IF(AND(H13<>"",H13>=F13),"SÍ","NO"),IF(G13="Baja",IF(AND(H13<>"",H13<=F13),"SÍ","NO"))))),"") -> SÍ | J13: =IF(B13="","",IFERROR(IF(I13="SÍ",D13*100,0),"")) -> 20
A14: =IF(B14="","",COUNTA($B$13:B14)) -> 2 | B14: Atender y conversar la totalidad de propuestas de mejora presentadas por el equipo en un plazo máximo de 2 meses desde su presentación. | C14: Individual | D14: 0.2 | E14: Número | F14: 1 | G14: Alza | H14: 1 | I14: =IFERROR(IF(OR(A14="",F14=""),"",IF(AND(G14<>"Alza",G14<>"Baja"),"",IF(G14="Alza",IF(AND(H14<>"",H14>=F14),"SÍ","NO"),IF(G14="Baja",IF(AND(H14<>"",H14<=F14),"SÍ","NO"))))),"") -> SÍ | J14: =IF(B14="","",IFERROR(IF(I14="SÍ",D14*100,0),"")) -> 20
A15: =IF(B15="","",COUNTA($B$13:B15)) -> 3 | B15: Desarrollo de dos conversaciones individuales de feedback al año con las personas bajo tu responsabilidad y/o con tu responsable directo para llevar a cabo una valoración mutua del desarrollo de la actividad. | C15: Individual | D15: 0.2 | E15: Número | F15: 2 | G15: Alza | H15: 2 | I15: =IFERROR(IF(OR(A15="",F15=""),"",IF(AND(G15<>"Alza",G15<>"Baja"),"",IF(G15="Alza",IF(AND(H15<>"",H15>=F15),"SÍ","NO"),IF(G15="Baja",IF(AND(H15<>"",H15<=F15),"SÍ","NO"))))),"") -> SÍ | J15: =IF(B15="","",IFERROR(IF(I15="SÍ",D15*100,0),"")) -> 20
A16: =IF(B16="","",COUNTA($B$13:B16)) -> 4 | B16: Presentar los objetivos de desempeño de todo su personal a la Comisión de Garantías de la Evaluación del Desempeño antes del 31 de mayo. | C16: Individual | D16: 0.12 | E16: Número | F16: 1 | G16: Alza | H16: 1 | I16: =IFERROR(IF(OR(A16="",F16=""),"",IF(AND(G16<>"Alza",G16<>"Baja"),"",IF(G16="Alza",IF(AND(H16<>"",H16>=F16),"SÍ","NO"),IF(G16="Baja",IF(AND(H16<>"",H16<=F16),"SÍ","NO"))))),"") -> SÍ | J16: =IF(B16="","",IFERROR(IF(I16="SÍ",D16*100,0),"")) -> 12
A17: =IF(B17="","",COUNTA($B$13:B17)) -> 5 | B17: Presentar el resultado de evaluación de objetivos de desempeño de todo su personal a la Comisión de Garantías de la Evaluación del Desempeño antes del 1 de septiembre. | C17: Individual | D17: 0.12 | E17: Número | F17: 1 | G17: Alza | H17: 1 | I17: =IFERROR(IF(OR(A17="",F17=""),"",IF(AND(G17<>"Alza",G17<>"Baja"),"",IF(G17="Alza",IF(AND(H17<>"",H17>=F17),"SÍ","NO"),IF(G17="Baja",IF(AND(H17<>"",H17<=F17),"SÍ","NO"))))),"") -> SÍ | J17: =IF(B17="","",IFERROR(IF(I17="SÍ",D17*100,0),"")) -> 12
A18: =IF(B18="","",COUNTA($B$13:B18)) -> 6 | B18: Gestión de las incidencias presentadas por los supervisados | C18: Individual | D18: =IF(B18="","",16%) -> 0.16 | E18: Porcentaje | F18: 80 | G18: Alza | H18: 80 | I18: =IFERROR(IF(OR(A18="",F18=""),"",IF(AND(G18<>"Alza",G18<>"Baja"),"",IF(G18="Alza",IF(AND(H18<>"",H18>=F18),"SÍ","NO"),IF(G18="Baja",IF(AND(H18<>"",H18<=F18),"SÍ","NO"))))),"") -> SÍ | J18: =IF(B18="","",IFERROR(IF(I18="SÍ",D18*100,0),"")) -> 16
C19: Total porcentaje asignado | D19: =SUM($D$13:$D$18) -> 1 | I19: Puntuación Final | J19: =IF(D19<>1,0,SUM($J$13:$J$18)) -> 100

Sheet Supervis@r_Int1
A1: Unidad Organizativa | C1: =IF(ISBLANK('Supervis@r'!$C$1),"",'Supervis@r'!$C$1) -> SERVICIOS OPERATIVOS | I1: Periodo Evaluado
A2: Programa | C2: =IF(ISBLANK('Supervis@r'!$C$2),"",'Supervis@r'!$C$2) -> ENCARGADOS Y CAPATACES | I2: ='Supervis@r'!$I$2 -> 2025 | J2: ='Supervis@r'!$J$2 -> 2026
A3: Supervisor/a | C3: =IF(ISBLANK('Supervis@r'!$C$3),"",CONCATENATE('Supervis@r'!$C$3," ",'Supervis@r'!$C$4,",",'Supervis@r'!$C$5)) -> JEFE JEFE,JOSE
A5: Puesto evaluado | C5: JEFE ADMINISTRACION | F5: DNI | G5: 23456780D | H5: ROL | I5: Supervisor/a Intermedio
A6: Apellido1 | C6: ADMIN
A7: Apellido2 | C7: ADMIN
A8: Nombre | C8: ANTONIO
A10: ID | B10: Objetivo (Descripción) | C10: Tipo Objetivo (Individual/Colectivo) | D10: Ponderación / Peso Objetivo (%) | E10: Categoría (Número/Porcentaje) | F10: Umbral (nivel de consecución esperado) | G10: Superación (Alza/Baja) | H10: Resultado Alcanzado | I10: Superación Umbral (SÍ/NO) | J10: Puntuación aportada (0 - 100)
A11: =IF(B11="","",COUNTA($B$11:B11)) -> 1 | B11: Realizar al menos 15 horas de formación "no obligatoria" en el periodo a evaluar, con las consideraciones recogidas en el Reglamento de ED | C11: Individual | D11: 0.2 | E11: Número | F11: 15 | G11: Alza | H11: 65 | I11: =IFERROR(IF(OR(A11="",F11=""),"",IF(AND(G11<>"Alza",G11<>"Baja"),"",IF(G11="Alza",IF(AND(H11<>"",H11>=F11),"SÍ","NO"),IF(G11="Baja",IF(AND(H11<>"",H11<=F11),"SÍ","NO"))))),"") -> SÍ | J11: =IF(B11="","",IFERROR(IF(I11="SÍ",D11*100,0),"")) -> 20
A12: =IF(B12="","",COUNTA($B$11:B12)) -> 2 | B12: Atender y conversar la totalidad de propuestas de mejora presentadas por el equipo en un plazo máximo de 2 meses desde su presentación. | C12: Individual | D12: 0.2 | E12: Número | F12: 1 | G12: Alza | H12: 1 | I12: =IFERROR(IF(OR(A12="",F12=""),"",IF(AND(G12<>"Alza",G12<>"Baja"),"",IF(G12="Alza",IF(AND(H12<>"",H12>=F12),"SÍ","NO"),IF(G12="Baja",IF(AND(H12<>"",H12<=F12),"SÍ","NO"))))),"") -> SÍ | J12: =IF(B12="","",IFERROR(IF(I12="SÍ",D12*100,0),"")) -> 20
A13: =IF(B13="","",COUNTA($B$11:B13)) -> 3 | B13: Desarrollo de dos conversaciones individuales de feedback al año con las personas bajo tu responsabilidad y/o con tu responsable directo para llevar a cabo una valoración mutua del desarrollo de la actividad. | C13: Individual | D13: 0.2 | E13: Número | F13: 2 | G13: Alza | H13: 2 | I13: =IFERROR(IF(OR(A13="",F13=""),"",IF(AND(G13<>"Alza",G13<>"Baja"),"",IF(G13="Alza",IF(AND(H13<>"",H13>=F13),"SÍ","NO"),IF(G13="Baja",IF(AND(H13<>"",H13<=F13),"SÍ","NO"))))),"") -> SÍ | J13: =IF(B13="","",IFERROR(IF(I13="SÍ",D13*100,0),"")) -> 20
A14: =IF(B14="","",COUNTA($B$11:B14)) -> 4 | B14: Presentar los objetivos de desempeño de todo su personal a la Comisión de Garantías de la Evaluación del Desempeño antes del 31 de mayo. | C14: Individual | D14: 0.12 | E14: Número | F14: 1 | G14: Alza | H14: 1 | I14: =IFERROR(IF(OR(A14="",F14=""),"",IF(AND(G14<>"Alza",G14<>"Baja"),"",IF(G14="Alza",IF(AND(H14<>"",H14>=F14),"SÍ","NO"),IF(G14="Baja",IF(AND(H14<>"",H14<=F14),"SÍ","NO"))))),"") -> SÍ | J14: =IF(B14="","",IFERROR(IF(I14="SÍ",D14*100,0),"")) -> 12
A15: =IF(B15="","",COUNTA($B$11:B15)) -> 5 | B15: Presentar el resultado de evaluación de objetivos de desempeño de todo su personal a la Comisión de Garantías de la Evaluación del Desempeño antes del 1 de septiembre. | C15: Individual | D15: 0.12 | E15: Número | F15: 1 | G15: Alza | H15: 1 | I15: =IFERROR(IF(OR(A15="",F15=""),"",IF(AND(G15<>"Alza",G15<>"Baja"),"",IF(G15="Alza",IF(AND(H15<>"",H15>=F15),"SÍ","NO"),IF(G15="Baja",IF(AND(H15<>"",H15<=F15),"SÍ","NO"))))),"") -> SÍ | J15: =IF(B15="","",IFERROR(IF(I15="SÍ",D15*100,0),"")) -> 12
A16: =IF(B16="","",COUNTA($B$11:B16)) -> 6 | B16: Gestión de incidencias presentadas por los Supervisados | C16: Individual | D16: =IF(B16="","",16%) -> 0.16 | E16: Porcentaje | F16: 80 | G16: Alza | H16: 80 | I16: =IFERROR(IF(OR(A16="",F16=""),"",IF(AND(G16<>"Alza",G16<>"Baja"),"",IF(G16="Alza",IF(AND(H16<>"",H16>=F16),"SÍ","NO"),IF(G16="Baja",IF(AND(H16<>"",H16<=F16),"SÍ","NO"))))),"") -> SÍ | J16: =IF(B16="","",IFERROR(IF(I16="SÍ",D16*100,0),"")) -> 16
C17: Total porcentaje asignado | D17: =SUM($D$11:$D$16) -> 1 | I17: Puntuación Final | J17: =IF(D17<>1,0,SUM($J$11:$J$16)) -> 100

Sheet Supervis@r_Int2
A1: Unidad Organizativa | C1: =IF(ISBLANK('Supervis@r'!$C$1),"",'Supervis@r'!$C$1) -> SERVICIOS OPERATIVOS | I1: Periodo Evaluado
A2: Programa | C2: =IF(ISBLANK('Supervis@r'!$C$2),"",'Supervis@r'!$C$2) -> ENCARGADOS Y CAPATACES | I2: ='Supervis@r'!$I$2 -> 2025 | J2: ='Supervis@r'!$J$2 -> 2026
A3: Supervisor/a | C3: =IF(ISBLANK('Supervis@r'!$C$3),"",CONCATENATE('Supervis@r'!$C$3," ",'Supervis@r'!$C$4,",",'Supervis@r'!$C$5)) -> JEFE JEFE,JOSE
A5: Puesto evaluado | C5: CAPATAZ LIMPIEZA MECANICA | F5: DNI | G5: 87654321F | H5: ROL | I5: Supervisor/a Intermedio
A6: Apellido1 | C6: MECANICO
A7: Apellido2 | C7: MECANICO
A8: Nombre | C8: EDUARDO
A10: ID | B10: Objetivo (Descripción) | C10: Tipo Objetivo (Individual/Colectivo) | D10: Ponderación / Peso Objetivo (%) | E10: Categoría (Número/Porcentaje) | F10: Umbral (nivel de consecución esperado) | G10: Superación (Alza/Baja) | H10: Resultado Alcanzado | I10: Superación Umbral (SÍ/NO) | J10: Puntuación aportada (0 - 100)
A11: =IF(B11="","",COUNTA($B$11:B11)) -> 1 | B11: Realizar al menos 15 horas de formación "no obligatoria" en el periodo a evaluar, con las consideraciones recogidas en el Reglamento de ED | C11: Individual | D11: 0.2 | E11: Número | F11: 15 | G11: Alza | H11: 50 | I11: =IFERROR(IF(OR(A11="",F11=""),"",IF(AND(G11<>"Alza",G11<>"Baja"),"",IF(G11="Alza",IF(AND(H11<>"",H11>=F11),"SÍ","NO"),IF(G11="Baja",IF(AND(H11<>"",H11<=F11),"SÍ","NO"))))),"") -> SÍ | J11: =IF(B11="","",IFERROR(IF(I11="SÍ",D11*100,0),"")) -> 20
A12: =IF(B12="","",COUNTA($B$11:B12)) -> 2 | B12: Atender y conversar la totalidad de propuestas de mejora presentadas por el equipo en un plazo máximo de 2 meses desde su presentación. | C12: Individual | D12: 0.2 | E12: Número | F12: 1 | G12: Alza | H12: 1 | I12: =IFERROR(IF(OR(A12="",F12=""),"",IF(AND(G12<>"Alza",G12<>"Baja"),"",IF(G12="Alza",IF(AND(H12<>"",H12>=F12),"SÍ","NO"),IF(G12="Baja",IF(AND(H12<>"",H12<=F12),"SÍ","NO"))))),"") -> SÍ | J12: =IF(B12="","",IFERROR(IF(I12="SÍ",D12*100,0),"")) -> 20
A13: =IF(B13="","",COUNTA($B$11:B13)) -> 3 | B13: Desarrollo de dos conversaciones individuales de feedback al año con las personas bajo tu responsabilidad y/o con tu responsable directo para llevar a cabo una valoración mutua del desarrollo de la actividad. | C13: Individual | D13: 0.2 | E13: Número | F13: 2 | G13: Alza | H13: 2 | I13: =IFERROR(IF(OR(A13="",F13=""),"",IF(AND(G13<>"Alza",G13<>"Baja"),"",IF(G13="Alza",IF(AND(H13<>"",H13>=F13),"SÍ","NO"),IF(G13="Baja",IF(AND(H13<>"",H13<=F13),"SÍ","NO"))))),"") -> SÍ | J13: =IF(B13="","",IFERROR(IF(I13="SÍ",D13*100,0),"")) -> 20
A14: =IF(B14="","",COUNTA($B$11:B14)) -> 4 | B14: Presentar los objetivos de desempeño de todo su personal a la Comisión de Garantías de la Evaluación del Desempeño antes del 31 de mayo. | C14: Individual | D14: 0.12 | E14: Número | F14: 1 | G14: Alza | H14: 1 | I14: =IFERROR(IF(OR(A14="",F14=""),"",IF(AND(G14<>"Alza",G14<>"Baja"),"",IF(G14="Alza",IF(AND(H14<>"",H14>=F14),"SÍ","NO"),IF(G14="Baja",IF(AND(H14<>"",H14<=F14),"SÍ","NO"))))),"") -> SÍ | J14: =IF(B14="","",IFERROR(IF(I14="SÍ",D14*100,0),"")) -> 12
A15: =IF(B15="","",COUNTA($B$11:B15)) -> 5 | B15: Presentar el resultado de evaluación de objetivos de desempeño de todo su personal a la Comisión de Garantías de la Evaluación del Desempeño antes del 1 de septiembre. | C15: Individual | D15: 0.12 | E15: Número | F15: 1 | G15: Alza | H15: 1 | I15: =IFERROR(IF(OR(A15="",F15=""),"",IF(AND(G15<>"Alza",G15<>"Baja"),"",IF(G15="Alza",IF(AND(H15<>"",H15>=F15),"SÍ","NO"),IF(G15="Baja",IF(AND(H15<>"",H15<=F15),"SÍ","NO"))))),"") -> SÍ | J15: =IF(B15="","",IFERROR(IF(I15="SÍ",D15*100,0),"")) -> 12
A16: =IF(B16="","",COUNTA($B$11:B16)) -> 6 | B16: Gestión de incidencias presentadas por los Supervisados | C16: Individual | D16: =IF(B16="","",16%) -> 0.16 | E16: Porcentaje | F16: 80 | G16: Alza | H16: 80 | I16: =IFERROR(IF(OR(A16="",F16=""),"",IF(AND(G16<>"Alza",G16<>"Baja"),"",IF(G16="Alza",IF(AND(H16<>"",H16>=F16),"SÍ","NO"),IF(G16="Baja",IF(AND(H16<>"",H16<=F16),"SÍ","NO"))))),"") -> SÍ | J16: =IF(B16="","",IFERROR(IF(I16="SÍ",D16*100,0),"")) -> 16
C17: Total porcentaje asignado | D17: =SUM($D$11:$D$16) -> 1 | I17: Puntuación Final | J17: =IF(D17<>1,0,SUM($J$11:$J$16)) -> 100

Sheet Supervis@r_Int3
A1: Unidad Organizativa | C1: =IF(ISBLANK('Supervis@r'!$C$1),"",'Supervis@r'!$C$1) -> SERVICIOS OPERATIVOS | I1: Periodo Evaluado
A2: Programa | C2: =IF(ISBLANK('Supervis@r'!$C$2),"",'Supervis@r'!$C$2) -> ENCARGADOS Y CAPATACES | I2: ='Supervis@r'!$I$2 -> 2025 | J2: ='Supervis@r'!$J$2 -> 2026
A3: Supervisor/a | C3: =IF(ISBLANK('Supervis@r'!$C$3),"",CONCATENATE('Supervis@r'!$C$3," ",'Supervis@r'!$C$4,",",'Supervis@r'!$C$5)) -> JEFE JEFE,JOSE
A5: Puesto evaluado | F5: DNI | H5: ROL | I5: Supervisor/a Intermedio
A6: Apellido1
A7: Apellido2
A8: Nombre
A10: ID | B10: Objetivo (Descripción) | C10: Tipo Objetivo (Individual/Colectivo) | D10: Ponderación / Peso Objetivo (%) | E10: Categoría (Número/Porcentaje) | F10: Umbral (nivel de consecución esperado) | G10: Superación (Alza/Baja) | H10: Resultado Alcanzado | I10: Superación Umbral (SÍ/NO) | J10: Puntuación aportada (0 - 100)
A11: =IF(B11="","",COUNTA($B$11:B11)) -> 1 | B11: Realizar al menos 15 horas de formación "no obligatoria" en el periodo a evaluar, con las consideraciones recogidas en el Reglamento de ED | C11: Individual | D11: 0.2 | E11: Número | F11: 15 | G11: Alza | H11: 30 | I11: =IFERROR(IF(OR(A11="",F11=""),"",IF(AND(G11<>"Alza",G11<>"Baja"),"",IF(G11="Alza",IF(AND(H11<>"",H11>=F11),"SÍ","NO"),IF(G11="Baja",IF(AND(H11<>"",H11<=F11),"SÍ","NO"))))),"") -> SÍ | J11: =IF(B11="","",IFERROR(IF(I11="SÍ",D11*100,0),"")) -> 20
A12: =IF(B12="","",COUNTA($B$11:B12)) -> 2 | B12: Atender y conversar la totalidad de propuestas de mejora presentadas por el equipo en un plazo máximo de 2 meses desde su presentación. | C12: Individual | D12: 0.2 | E12: Número | F12: 1 | G12: Alza | H12: 1 | I12: =IFERROR(IF(OR(A12="",F12=""),"",IF(AND(G12<>"Alza",G12<>"Baja"),"",IF(G12="Alza",IF(AND(H12<>"",H12>=F12),"SÍ","NO"),IF(G12="Baja",IF(AND(H12<>"",H12<=F12),"SÍ","NO"))))),"") -> SÍ | J12: =IF(B12="","",IFERROR(IF(I12="SÍ",D12*100,0),"")) -> 20
A13: =IF(B13="","",COUNTA($B$11:B13)) -> 3 | B13: Desarrollo de dos conversaciones individuales de feedback al año con las personas bajo tu responsabilidad y/o con tu responsable directo para llevar a cabo una valoración mutua del desarrollo de la actividad. | C13: Individual | D13: 0.2 | E13: Número | F13: 2 | G13: Alza | H13: 2 | I13: =IFERROR(IF(OR(A13="",F13=""),"",IF(AND(G13<>"Alza",G13<>"Baja"),"",IF(G13="Alza",IF(AND(H13<>"",H13>=F13),"SÍ","NO"),IF(G13="Baja",IF(AND(H13<>"",H13<=F13),"SÍ","NO"))))),"") -> SÍ | J13: =IF(B13="","",IFERROR(IF(I13="SÍ",D13*100,0),"")) -> 20
A14: =IF(B14="","",COUNTA($B$11:B14)) -> 4 | B14: Presentar los objetivos de desempeño de todo su personal a la Comisión de Garantías de la Evaluación del Desempeño antes del 31 de mayo. | C14: Individual | D14: 0.12 | E14: Número | F14: 1 | G14: Alza | H14: 1 | I14: =IFERROR(IF(OR(A14="",F14=""),"",IF(AND(G14<>"Alza",G14<>"Baja"),"",IF(G14="Alza",IF(AND(H14<>"",H14>=F14),"SÍ","NO"),IF(G14="Baja",IF(AND(H14<>"",H14<=F14),"SÍ","NO"))))),"") -> SÍ | J14: =IF(B14="","",IFERROR(IF(I14="SÍ",D14*100,0),"")) -> 12
A15: =IF(B15="","",COUNTA($B$11:B15)) -> 5 | B15: Presentar el resultado de evaluación de objetivos de desempeño de todo su personal a la Comisión de Garantías de la Evaluación del Desempeño antes del 1 de septiembre. | C15: Individual | D15: 0.12 | E15: Número | F15: 1 | G15: Alza | H15: 1 | I15: =IFERROR(IF(OR(A15="",F15=""),"",IF(AND(G15<>"Alza",G15<>"Baja"),"",IF(G15="Alza",IF(AND(H15<>"",H15>=F15),"SÍ","NO"),IF(G15="Baja",IF(AND(H15<>"",H15<=F15),"SÍ","NO"))))),"") -> SÍ | J15: =IF(B15="","",IFERROR(IF(I15="SÍ",D15*100,0),"")) -> 12
A16: =IF(B16="","",COUNTA($B$11:B16)) -> 6 | B16: Gestión de incidencias presentadas por los Supervisados | C16: Individual | D16: =IF(B16="","",16%) -> 0.16 | E16: Porcentaje | F16: 80 | G16: Alza | H16: 80 | I16: =IFERROR(IF(OR(A16="",F16=""),"",IF(AND(G16<>"Alza",G16<>"Baja"),"",IF(G16="Alza",IF(AND(H16<>"",H16>=F16),"SÍ","NO"),IF(G16="Baja",IF(AND(H16<>"",H16<=F16),"SÍ","NO"))))),"") -> SÍ | J16: =IF(B16="","",IFERROR(IF(I16="SÍ",D16*100,0),"")) -> 16
C17: Total porcentaje asignado | D17: =SUM($D$11:$D$16) -> 1 | I17: Puntuación Final | J17: =IF(D17<>1,0,SUM($J$11:$J$16)) -> 100

Sheet Supervis@r_Int4
A1: Unidad Organizativa | C1: =IF(ISBLANK('Supervis@r'!$C$1),"",'Supervis@r'!$C$1) -> SERVICIOS OPERATIVOS | I1: Periodo Evaluado
A2: Programa | C2: =IF(ISBLANK('Supervis@r'!$C$2),"",'Supervis@r'!$C$2) -> ENCARGADOS Y CAPATACES | I2: ='Supervis@r'!$I$2 -> 2025 | J2: ='Supervis@r'!$J$2 -> 2026
A3: Supervisor/a | C3: =IF(ISBLANK('Supervis@r'!$C$3),"",CONCATENATE('Supervis@r'!$C$3," ",'Supervis@r'!$C$4,",",'Supervis@r'!$C$5)) -> JEFE JEFE,JOSE
A5: Puesto evaluado | F5: DNI | H5: ROL | I5: Supervisor/a Intermedio
A6: Apellido1
A7: Apellido2
A8: Nombre
A10: ID | B10: Objetivo (Descripción) | C10: Tipo Objetivo (Individual/Colectivo) | D10: Ponderación / Peso Objetivo (%) | E10: Categoría (Número/Porcentaje) | F10: Umbral (nivel de consecución esperado) | G10: Superación (Alza/Baja) | H10: Resultado Alcanzado | I10: Superación Umbral (SÍ/NO) | J10: Puntuación aportada (0 - 100)
A11: =IF(B11="","",COUNTA($B$11:B11)) -> 1 | B11: Realizar al menos 15 horas de formación "no obligatoria" en el periodo a evaluar, con las consideraciones recogidas en el Reglamento de ED | C11: Individual | D11: 0.2 | E11: Número | F11: 15 | G11: Alza | H11: 50 | I11: =IFERROR(IF(OR(A11="",F11=""),"",IF(AND(G11<>"Alza",G11<>"Baja"),"",IF(G11="Alza",IF(AND(H11<>"",H11>=F11),"SÍ","NO"),IF(G11="Baja",IF(AND(H11<>"",H11<=F11),"SÍ","NO"))))),"") -> SÍ | J11: =IF(B11="","",IFERROR(IF(I11="SÍ",D11*100,0),"")) -> 20
A12: =IF(B12="","",COUNTA($B$11:B12)) -> 2 | B12: Atender y conversar la totalidad de propuestas de mejora presentadas por el equipo en un plazo máximo de 2 meses desde su presentación. | C12: Individual | D12: 0.2 | E12: Número | F12: 1 | G12: Alza | H12: 1 | I12: =IFERROR(IF(OR(A12="",F12=""),"",IF(AND(G12<>"Alza",G12<>"Baja"),"",IF(G12="Alza",IF(AND(H12<>"",H12>=F12),"SÍ","NO"),IF(G12="Baja",IF(AND(H12<>"",H12<=F12),"SÍ","NO"))))),"") -> SÍ | J12: =IF(B12="","",IFERROR(IF(I12="SÍ",D12*100,0),"")) -> 20
A13: =IF(B13="","",COUNTA($B$11:B13)) -> 3 | B13: Desarrollo de dos conversaciones individuales de feedback al año con las personas bajo tu responsabilidad y/o con tu responsable directo para llevar a cabo una valoración mutua del desarrollo de la actividad. | C13: Individual | D13: 0.2 | E13: Número | F13: 2 | G13: Alza | H13: 2 | I13: =IFERROR(IF(OR(A13="",F13=""),"",IF(AND(G13<>"Alza",G13<>"Baja"),"",IF(G13="Alza",IF(AND(H13<>"",H13>=F13),"SÍ","NO"),IF(G13="Baja",IF(AND(H13<>"",H13<=F13),"SÍ","NO"))))),"") -> SÍ | J13: =IF(B13="","",IFERROR(IF(I13="SÍ",D13*100,0),"")) -> 20
A14: =IF(B14="","",COUNTA($B$11:B14)) -> 4 | B14: Presentar los objetivos de desempeño de todo su personal a la Comisión de Garantías de la Evaluación del Desempeño antes del 31 de mayo. | C14: Individual | D14: 0.12 | E14: Número | F14: 1 | G14: Alza | H14: 1 | I14: =IFERROR(IF(OR(A14="",F14=""),"",IF(AND(G14<>"Alza",G14<>"Baja"),"",IF(G14="Alza",IF(AND(H14<>"",H14>=F14),"SÍ","NO"),IF(G14="Baja",IF(AND(H14<>"",H14<=F14),"SÍ","NO"))))),"") -> SÍ | J14: =IF(B14="","",IFERROR(IF(I14="SÍ",D14*100,0),"")) -> 12
A15: =IF(B15="","",COUNTA($B$11:B15)) -> 5 | B15: Presentar el resultado de evaluación de objetivos de desempeño de todo su personal a la Comisión de Garantías de la Evaluación del Desempeño antes del 1 de septiembre. | C15: Individual | D15: 0.12 | E15: Número | F15: 1 | G15: Alza | H15: 1 | I15: =IFERROR(IF(OR(A15="",F15=""),"",IF(AND(G15<>"Alza",G15<>"Baja"),"",IF(G15="Alza",IF(AND(H15<>"",H15>=F15),"SÍ","NO"),IF(G15="Baja",IF(AND(H15<>"",H15<=F15),"SÍ","NO"))))),"") -> SÍ | J15: =IF(B15="","",IFERROR(IF(I15="SÍ",D15*100,0),"")) -> 12
A16: =IF(B16="","",COUNTA($B$11:B16)) -> 6 | B16: Gestión de incidencias presentadas por los Supervisados | C16: Individual | D16: =IF(B16="","",16%) -> 0.16 | E16: Porcentaje | F16: 80 | G16: Alza | H16: 80 | I16: =IFERROR(IF(OR(A16="",F16=""),"",IF(AND(G16<>"Alza",G16<>"Baja"),"",IF(G16="Alza",IF(AND(H16<>"",H16>=F16),"SÍ","NO"),IF(G16="Baja",IF(AND(H16<>"",H16<=F16),"SÍ","NO"))))),"") -> SÍ | J16: =IF(B16="","",IFERROR(IF(I16="SÍ",D16*100,0),"")) -> 16
C17: Total porcentaje asignado | D17: =SUM($D$11:$D$16) -> 1 | I17: Puntuación Final | J17: =IF(D17<>1,0,SUM($J$11:$J$16)) -> 100

Sheet Supervis@r_Int5
A1: Unidad Organizativa | C1: =IF(ISBLANK('Supervis@r'!$C$1),"",'Supervis@r'!$C$1) -> SERVICIOS OPERATIVOS | I1: Periodo Evaluado
A2: Programa | C2: =IF(ISBLANK('Supervis@r'!$C$2),"",'Supervis@r'!$C$2) -> ENCARGADOS Y CAPATACES | I2: ='Supervis@r'!$I$2 -> 2025 | J2: ='Supervis@r'!$J$2 -> 2026
A3: Supervisor/a | C3: =IF(ISBLANK('Supervis@r'!$C$3),"",CONCATENATE('Supervis@r'!$C$3," ",'Supervis@r'!$C$4,",",'Supervis@r'!$C$5)) -> JEFE JEFE,JOSE
A5: Puesto evaluado | F5: DNI | H5: ROL | I5: Supervisor/a Intermedio
A6: Apellido1
A7: Apellido2
A8: Nombre
A10: ID | B10: Objetivo (Descripción) | C10: Tipo Objetivo (Individual/Colectivo) | D10: Ponderación / Peso Objetivo (%) | E10: Categoría (Número/Porcentaje) | F10: Umbral (nivel de consecución esperado) | G10: Superación (Alza/Baja) | H10: Resultado Alcanzado | I10: Superación Umbral (SÍ/NO) | J10: Puntuación aportada (0 - 100)
A11: =IF(B11="","",COUNTA($B$11:B11)) -> 1 | B11: Realizar al menos 15 horas de formación "no obligatoria" en el periodo a evaluar, con las consideraciones recogidas en el Reglamento de ED | C11: Individual | D11: 0.2 | E11: Número | F11: 15 | G11: Alza | H11: 50 | I11: =IFERROR(IF(OR(A11="",F11=""),"",IF(AND(G11<>"Alza",G11<>"Baja"),"",IF(G11="Alza",IF(AND(H11<>"",H11>=F11),"SÍ","NO"),IF(G11="Baja",IF(AND(H11<>"",H11<=F11),"SÍ","NO"))))),"") -> SÍ | J11: =IF(B11="","",IFERROR(IF(I11="SÍ",D11*100,0),"")) -> 20
A12: =IF(B12="","",COUNTA($B$11:B12)) -> 2 | B12: Atender y conversar la totalidad de propuestas de mejora presentadas por el equipo en un plazo máximo de 2 meses desde su presentación. | C12: Individual | D12: 0.2 | E12: Número | F12: 1 | G12: Alza | H12: 1 | I12: =IFERROR(IF(OR(A12="",F12=""),"",IF(AND(G12<>"Alza",G12<>"Baja"),"",IF(G12="Alza",IF(AND(H12<>"",H12>=F12),"SÍ","NO"),IF(G12="Baja",IF(AND(H12<>"",H12<=F12),"SÍ","NO"))))),"") -> SÍ | J12: =IF(B12="","",IFERROR(IF(I12="SÍ",D12*100,0),"")) -> 20
A13: =IF(B13="","",COUNTA($B$11:B13)) -> 3 | B13: Desarrollo de dos conversaciones individuales de feedback al año con las personas bajo tu responsabilidad y/o con tu responsable directo para llevar a cabo una valoración mutua del desarrollo de la actividad. | C13: Individual | D13: 0.2 | E13: Número | F13: 2 | G13: Alza | H13: 2 | I13: =IFERROR(IF(OR(A13="",F13=""),"",IF(AND(G13<>"Alza",G13<>"Baja"),"",IF(G13="Alza",IF(AND(H13<>"",H13>=F13),"SÍ","NO"),IF(G13="Baja",IF(AND(H13<>"",H13<=F13),"SÍ","NO"))))),"") -> SÍ | J13: =IF(B13="","",IFERROR(IF(I13="SÍ",D13*100,0),"")) -> 20
A14: =IF(B14="","",COUNTA($B$11:B14)) -> 4 | B14: Presentar los objetivos de desempeño de todo su personal a la Comisión de Garantías de la Evaluación del Desempeño antes del 31 de mayo. | C14: Individual | D14: 0.12 | E14: Número | F14: 1 | G14: Alza | H14: 1 | I14: =IFERROR(IF(OR(A14="",F14=""),"",IF(AND(G14<>"Alza",G14<>"Baja"),"",IF(G14="Alza",IF(AND(H14<>"",H14>=F14),"SÍ","NO"),IF(G14="Baja",IF(AND(H14<>"",H14<=F14),"SÍ","NO"))))),"") -> SÍ | J14: =IF(B14="","",IFERROR(IF(I14="SÍ",D14*100,0),"")) -> 12
A15: =IF(B15="","",COUNTA($B$11:B15)) -> 5 | B15: Presentar el resultado de evaluación de objetivos de desempeño de todo su personal a la Comisión de Garantías de la Evaluación del Desempeño antes del 1 de septiembre. | C15: Individual | D15: 0.12 | E15: Número | F15: 1 | G15: Alza | H15: 1 | I15: =IFERROR(IF(OR(A15="",F15=""),"",IF(AND(G15<>"Alza",G15<>"Baja"),"",IF(G15="Alza",IF(AND(H15<>"",H15>=F15),"SÍ","NO"),IF(G15="Baja",IF(AND(H15<>"",H15<=F15),"SÍ","NO"))))),"") -> SÍ | J15: =IF(B15="","",IFERROR(IF(I15="SÍ",D15*100,0),"")) -> 12
A16: =IF(B16="","",COUNTA($B$11:B16)) -> 6 | B16: Gestión de incidencias presentadas por los Supervisados | C16: Individual | D16: =IF(B16="","",16%) -> 0.16 | E16: Porcentaje | F16: 80 | G16: Alza | H16: 80 | I16: =IFERROR(IF(OR(A16="",F16=""),"",IF(AND(G16<>"Alza",G16<>"Baja"),"",IF(G16="Alza",IF(AND(H16<>"",H16>=F16),"SÍ","NO"),IF(G16="Baja",IF(AND(H16<>"",H16<=F16),"SÍ","NO"))))),"") -> SÍ | J16: =IF(B16="","",IFERROR(IF(I16="SÍ",D16*100,0),"")) -> 16
C17: Total porcentaje asignado | D17: =SUM($D$11:$D$16) -> 1 | I17: Puntuación Final | J17: =IF(D17<>1,0,SUM($J$11:$J$16)) -> 100

Sheet Supervis@r_Int6
A1: Unidad Organizativa | C1: =IF(ISBLANK('Supervis@r'!$C$1),"",'Supervis@r'!$C$1) -> SERVICIOS OPERATIVOS | I1: Periodo Evaluado
A2: Programa | C2: =IF(ISBLANK('Supervis@r'!$C$2),"",'Supervis@r'!$C$2) -> ENCARGADOS Y CAPATACES | I2: ='Supervis@r'!$I$2 -> 2025 | J2: ='Supervis@r'!$J$2 -> 2026
A3: Supervisor/a | C3: =IF(ISBLANK('Supervis@r'!$C$3),"",CONCATENATE('Supervis@r'!$C$3," ",'Supervis@r'!$C$4,",",'Supervis@r'!$C$5)) -> JEFE JEFE,JOSE
A5: Puesto evaluado | F5: DNI | H5: ROL | I5: Supervisor/a Intermedio
A6: Apellido1
A7: Apellido2
A8: Nombre
A10: ID | B10: Objetivo (Descripción) | C10: Tipo Objetivo (Individual/Colectivo) | D10: Ponderación / Peso Objetivo (%) | E10: Categoría (Número/Porcentaje) | F10: Umbral (nivel de consecución esperado) | G10: Superación (Alza/Baja) | H10: Resultado Alcanzado | I10: Superación Umbral (SÍ/NO) | J10: Puntuación aportada (0 - 100)
A11: =IF(B11="","",COUNTA($B$11:B11)) -> 1 | B11: Realizar al menos 15 horas de formación "no obligatoria" en el periodo a evaluar, con las consideraciones recogidas en el Reglamento de ED | C11: Individual | D11: 0.2 | E11: Número | F11: 15 | G11: Alza | H11: 50 | I11: =IFERROR(IF(OR(A11="",F11=""),"",IF(AND(G11<>"Alza",G11<>"Baja"),"",IF(G11="Alza",IF(AND(H11<>"",H11>=F11),"SÍ","NO"),IF(G11="Baja",IF(AND(H11<>"",H11<=F11),"SÍ","NO"))))),"") -> SÍ | J11: =IF(B11="","",IFERROR(IF(I11="SÍ",D11*100,0),"")) -> 20
A12: =IF(B12="","",COUNTA($B$11:B12)) -> 2 | B12: Atender y conversar la totalidad de propuestas de mejora presentadas por el equipo en un plazo máximo de 2 meses desde su presentación. | C12: Individual | D12: 0.2 | E12: Número | F12: 1 | G12: Alza | H12: 1 | I12: =IFERROR(IF(OR(A12="",F12=""),"",IF(AND(G12<>"Alza",G12<>"Baja"),"",IF(G12="Alza",IF(AND(H12<>"",H12>=F12),"SÍ","NO"),IF(G12="Baja",IF(AND(H12<>"",H12<=F12),"SÍ","NO"))))),"") -> SÍ | J12: =IF(B12="","",IFERROR(IF(I12="SÍ",D12*100,0),"")) -> 20
A13: =IF(B13="","",COUNTA($B$11:B13)) -> 3 | B13: Desarrollo de dos conversaciones individuales de feedback al año con las personas bajo tu responsabilidad y/o con tu responsable directo para llevar a cabo una valoración mutua del desarrollo de la actividad. | C13: Individual | D13: 0.2 | E13: Número | F13: 2 | G13: Alza | H13: 2 | I13: =IFERROR(IF(OR(A13="",F13=""),"",IF(AND(G13<>"Alza",G13<>"Baja"),"",IF(G13="Alza",IF(AND(H13<>"",H13>=F13),"SÍ","NO"),IF(G13="Baja",IF(AND(H13<>"",H13<=F13),"SÍ","NO"))))),"") -> SÍ | J13: =IF(B13="","",IFERROR(IF(I13="SÍ",D13*100,0),"")) -> 20
A14: =IF(B14="","",COUNTA($B$11:B14)) -> 4 | B14: Presentar los objetivos de desempeño de todo su personal a la Comisión de Garantías de la Evaluación del Desempeño antes del 31 de mayo. | C14: Individual | D14: 0.12 | E14: Número | F14: 1 | G14: Alza | H14: 1 | I14: =IFERROR(IF(OR(A14="",F14=""),"",IF(AND(G14<>"Alza",G14<>"Baja"),"",IF(G14="Alza",IF(AND(H14<>"",H14>=F14),"SÍ","NO"),IF(G14="Baja",IF(AND(H14<>"",H14<=F14),"SÍ","NO"))))),"") -> SÍ | J14: =IF(B14="","",IFERROR(IF(I14="SÍ",D14*100,0),"")) -> 12
A15: =IF(B15="","",COUNTA($B$11:B15)) -> 5 | B15: Presentar el resultado de evaluación de objetivos de desempeño de todo su personal a la Comisión de Garantías de la Evaluación del Desempeño antes del 1 de septiembre. | C15: Individual | D15: 0.12 | E15: Número | F15: 1 | G15: Alza | H15: 1 | I15: =IFERROR(IF(OR(A15="",F15=""),"",IF(AND(G15<>"Alza",G15<>"Baja"),"",IF(G15="Alza",IF(AND(H15<>"",H15>=F15),"SÍ","NO"),IF(G15="Baja",IF(AND(H15<>"",H15<=F15),"SÍ","NO"))))),"") -> SÍ | J15: =IF(B15="","",IFERROR(IF(I15="SÍ",D15*100,0),"")) -> 12
A16: =IF(B16="","",COUNTA($B$11:B16)) -> 6 | B16: Gestión de incidencias presentadas por los Supervisados | C16: Individual | D16: =IF(B16="","",16%) -> 0.16 | E16: Porcentaje | F16: 80 | G16: Alza | H16: 80 | I16: =IFERROR(IF(OR(A16="",F16=""),"",IF(AND(G16<>"Alza",G16<>"Baja"),"",IF(G16="Alza",IF(AND(H16<>"",H16>=F16),"SÍ","NO"),IF(G16="Baja",IF(AND(H16<>"",H16<=F16),"SÍ","NO"))))),"") -> SÍ | J16: =IF(B16="","",IFERROR(IF(I16="SÍ",D16*100,0),"")) -> 16
C17: Total porcentaje asignado | D17: =SUM($D$11:$D$16) -> 1 | I17: Puntuación Final | J17: =IF(D17<>1,0,SUM($J$11:$J$16)) -> 100

Sheet Supervis@r_Int7
A1: Unidad Organizativa | C1: =IF(ISBLANK('Supervis@r'!$C$1),"",'Supervis@r'!$C$1) -> SERVICIOS OPERATIVOS | I1: Periodo Evaluado
A2: Programa | C2: =IF(ISBLANK('Supervis@r'!$C$2),"",'Supervis@r'!$C$2) -> ENCARGADOS Y CAPATACES | I2: ='Supervis@r'!$I$2 -> 2025 | J2: ='Supervis@r'!$J$2 -> 2026
A3: Supervisor/a | C3: =IF(ISBLANK('Supervis@r'!$C$3),"",CONCATENATE('Supervis@r'!$C$3," ",'Supervis@r'!$C$4,",",'Supervis@r'!$C$5)) -> JEFE JEFE,JOSE
A5: Puesto evaluado | F5: DNI | H5: ROL | I5: Supervisor/a Intermedio
A6: Apellido1
A7: Apellido2
A8: Nombre
A10: ID | B10: Objetivo (Descripción) | C10: Tipo Objetivo (Individual/Colectivo) | D10: Ponderación / Peso Objetivo (%) | E10: Categoría (Número/Porcentaje) | F10: Umbral (nivel de consecución esperado) | G10: Superación (Alza/Baja) | H10: Resultado Alcanzado | I10: Superación Umbral (SÍ/NO) | J10: Puntuación aportada (0 - 100)
A11: =IF(B11="","",COUNTA($B$11:B11)) -> 1 | B11: Realizar al menos 15 horas de formación "no obligatoria" en el periodo a evaluar, con las consideraciones recogidas en el Reglamento de ED | C11: Individual | D11: 0.2 | E11: Número | F11: 15 | G11: Alza | H11: 50 | I11: =IFERROR(IF(OR(A11="",F11=""),"",IF(AND(G11<>"Alza",G11<>"Baja"),"",IF(G11="Alza",IF(AND(H11<>"",H11>=F11),"SÍ","NO"),IF(G11="Baja",IF(AND(H11<>"",H11<=F11),"SÍ","NO"))))),"") -> SÍ | J11: =IF(B11="","",IFERROR(IF(I11="SÍ",D11*100,0),"")) -> 20
A12: =IF(B12="","",COUNTA($B$11:B12)) -> 2 | B12: Atender y conversar la totalidad de propuestas de mejora presentadas por el equipo en un plazo máximo de 2 meses desde su presentación. | C12: Individual | D12: 0.2 | E12: Número | F12: 1 | G12: Alza | H12: 1 | I12: =IFERROR(IF(OR(A12="",F12=""),"",IF(AND(G12<>"Alza",G12<>"Baja"),"",IF(G12="Alza",IF(AND(H12<>"",H12>=F12),"SÍ","NO"),IF(G12="Baja",IF(AND(H12<>"",H12<=F12),"SÍ","NO"))))),"") -> SÍ | J12: =IF(B12="","",IFERROR(IF(I12="SÍ",D12*100,0),"")) -> 20
A13: =IF(B13="","",COUNTA($B$11:B13)) -> 3 | B13: Desarrollo de dos conversaciones individuales de feedback al año con las personas bajo tu responsabilidad y/o con tu responsable directo para llevar a cabo una valoración mutua del desarrollo de la actividad. | C13: Individual | D13: 0.2 | E13: Número | F13: 2 | G13: Alza | H13: 2 | I13: =IFERROR(IF(OR(A13="",F13=""),"",IF(AND(G13<>"Alza",G13<>"Baja"),"",IF(G13="Alza",IF(AND(H13<>"",H13>=F13),"SÍ","NO"),IF(G13="Baja",IF(AND(H13<>"",H13<=F13),"SÍ","NO"))))),"") -> SÍ | J13: =IF(B13="","",IFERROR(IF(I13="SÍ",D13*100,0),"")) -> 20
A14: =IF(B14="","",COUNTA($B$11:B14)) -> 4 | B14: Presentar los objetivos de desempeño de todo su personal a la Comisión de Garantías de la Evaluación del Desempeño antes del 31 de mayo. | C14: Individual | D14: 0.12 | E14: Número | F14: 1 | G14: Alza | H14: 1 | I14: =IFERROR(IF(OR(A14="",F14=""),"",IF(AND(G14<>"Alza",G14<>"Baja"),"",IF(G14="Alza",IF(AND(H14<>"",H14>=F14),"SÍ","NO"),IF(G14="Baja",IF(AND(H14<>"",H14<=F14),"SÍ","NO"))))),"") -> SÍ | J14: =IF(B14="","",IFERROR(IF(I14="SÍ",D14*100,0),"")) -> 12
A15: =IF(B15="","",COUNTA($B$11:B15)) -> 5 | B15: Presentar el resultado de evaluación de objetivos de desempeño de todo su personal a la Comisión de Garantías de la Evaluación del Desempeño antes del 1 de septiembre. | C15: Individual | D15: 0.12 | E15: Número | F15: 1 | G15: Alza | H15: 1 | I15: =IFERROR(IF(OR(A15="",F15=""),"",IF(AND(G15<>"Alza",G15<>"Baja"),"",IF(G15="Alza",IF(AND(H15<>"",H15>=F15),"SÍ","NO"),IF(G15="Baja",IF(AND(H15<>"",H15<=F15),"SÍ","NO"))))),"") -> SÍ | J15: =IF(B15="","",IFERROR(IF(I15="SÍ",D15*100,0),"")) -> 12
A16: =IF(B16="","",COUNTA($B$11:B16)) -> 6 | B16: Gestión de incidencias presentadas por los Supervisados | C16: Individual | D16: =IF(B16="","",16%) -> 0.16 | E16: Porcentaje | F16: 80 | G16: Alza | H16: 80 | I16: =IFERROR(IF(OR(A16="",F16=""),"",IF(AND(G16<>"Alza",G16<>"Baja"),"",IF(G16="Alza",IF(AND(H16<>"",H16>=F16),"SÍ","NO"),IF(G16="Baja",IF(AND(H16<>"",H16<=F16),"SÍ","NO"))))),"") -> SÍ | J16: =IF(B16="","",IFERROR(IF(I16="SÍ",D16*100,0),"")) -> 16
C17: Total porcentaje asignado | D17: =SUM($D$11:$D$16) -> 1 | I17: Puntuación Final | J17: =IF(D17<>1,0,SUM($J$11:$J$16)) -> 100

Sheet Supervis@r_Int8
A1: Unidad Organizativa | C1: =IF(ISBLANK('Supervis@r'!$C$1),"",'Supervis@r'!$C$1) -> SERVICIOS OPERATIVOS | I1: Periodo Evaluado
A2: Programa | C2: =IF(ISBLANK('Supervis@r'!$C$2),"",'Supervis@r'!$C$2) -> ENCARGADOS Y CAPATACES | I2: ='Supervis@r'!$I$2 -> 2025 | J2: ='Supervis@r'!$J$2 -> 2026
A3: Supervisor/a | C3: =IF(ISBLANK('Supervis@r'!$C$3),"",CONCATENATE('Supervis@r'!$C$3," ",'Supervis@r'!$C$4,",",'Supervis@r'!$C$5)) -> JEFE JEFE,JOSE
A5: Puesto evaluado | F5: DNI | H5: ROL | I5: Supervisor/a Intermedio
A6: Apellido1
A7: Apellido2
A8: Nombre
A10: ID | B10: Objetivo (Descripción) | C10: Tipo Objetivo (Individual/Colectivo) | D10: Ponderación / Peso Objetivo (%) | E10: Categoría (Número/Porcentaje) | F10: Umbral (nivel de consecución esperado) | G10: Superación (Alza/Baja) | H10: Resultado Alcanzado | I10: Superación Umbral (SÍ/NO) | J10: Puntuación aportada (0 - 100)
A11: =IF(B11="","",COUNTA($B$11:B11)) -> 1 | B11: Realizar al menos 15 horas de formación "no obligatoria" en el periodo a evaluar, con las consideraciones recogidas en el Reglamento de ED | C11: Individual | D11: 0.2 | E11: Número | F11: 15 | G11: Alza | H11: 25 | I11: =IFERROR(IF(OR(A11="",F11=""),"",IF(AND(G11<>"Alza",G11<>"Baja"),"",IF(G11="Alza",IF(AND(H11<>"",H11>=F11),"SÍ","NO"),IF(G11="Baja",IF(AND(H11<>"",H11<=F11),"SÍ","NO"))))),"") -> SÍ | J11: =IF(B11="","",IFERROR(IF(I11="SÍ",D11*100,0),"")) -> 20
A12: =IF(B12="","",COUNTA($B$11:B12)) -> 2 | B12: Atender y conversar la totalidad de propuestas de mejora presentadas por el equipo en un plazo máximo de 2 meses desde su presentación. | C12: Individual | D12: 0.2 | E12: Número | F12: 1 | G12: Alza | H12: 1 | I12: =IFERROR(IF(OR(A12="",F12=""),"",IF(AND(G12<>"Alza",G12<>"Baja"),"",IF(G12="Alza",IF(AND(H12<>"",H12>=F12),"SÍ","NO"),IF(G12="Baja",IF(AND(H12<>"",H12<=F12),"SÍ","NO"))))),"") -> SÍ | J12: =IF(B12="","",IFERROR(IF(I12="SÍ",D12*100,0),"")) -> 20
A13: =IF(B13="","",COUNTA($B$11:B13)) -> 3 | B13: Desarrollo de dos conversaciones individuales de feedback al año con las personas bajo tu responsabilidad y/o con tu responsable directo para llevar a cabo una valoración mutua del desarrollo de la actividad. | C13: Individual | D13: 0.2 | E13: Número | F13: 2 | G13: Alza | H13: 2 | I13: =IFERROR(IF(OR(A13="",F13=""),"",IF(AND(G13<>"Alza",G13<>"Baja"),"",IF(G13="Alza",IF(AND(H13<>"",H13>=F13),"SÍ","NO"),IF(G13="Baja",IF(AND(H13<>"",H13<=F13),"SÍ","NO"))))),"") -> SÍ | J13: =IF(B13="","",IFERROR(IF(I13="SÍ",D13*100,0),"")) -> 20
A14: =IF(B14="","",COUNTA($B$11:B14)) -> 4 | B14: Presentar los objetivos de desempeño de todo su personal a la Comisión de Garantías de la Evaluación del Desempeño antes del 31 de mayo. | C14: Individual | D14: 0.12 | E14: Número | F14: 1 | G14: Alza | H14: 1 | I14: =IFERROR(IF(OR(A14="",F14=""),"",IF(AND(G14<>"Alza",G14<>"Baja"),"",IF(G14="Alza",IF(AND(H14<>"",H14>=F14),"SÍ","NO"),IF(G14="Baja",IF(AND(H14<>"",H14<=F14),"SÍ","NO"))))),"") -> SÍ | J14: =IF(B14="","",IFERROR(IF(I14="SÍ",D14*100,0),"")) -> 12
A15: =IF(B15="","",COUNTA($B$11:B15)) -> 5 | B15: Presentar el resultado de evaluación de objetivos de desempeño de todo su personal a la Comisión de Garantías de la Evaluación del Desempeño antes del 1 de septiembre. | C15: Individual | D15: 0.12 | E15: Número | F15: 1 | G15: Alza | H15: 1 | I15: =IFERROR(IF(OR(A15="",F15=""),"",IF(AND(G15<>"Alza",G15<>"Baja"),"",IF(G15="Alza",IF(AND(H15<>"",H15>=F15),"SÍ","NO"),IF(G15="Baja",IF(AND(H15<>"",H15<=F15),"SÍ","NO"))))),"") -> SÍ | J15: =IF(B15="","",IFERROR(IF(I15="SÍ",D15*100,0),"")) -> 12
A16: =IF(B16="","",COUNTA($B$11:B16)) -> 6 | B16: Gestión de incidencias presentadas por los Supervisados | C16: Individual | D16: =IF(B16="","",16%) -> 0.16 | E16: Porcentaje | F16: 80 | G16: Alza | H16: 80 | I16: =IFERROR(IF(OR(A16="",F16=""),"",IF(AND(G16<>"Alza",G16<>"Baja"),"",IF(G16="Alza",IF(AND(H16<>"",H16>=F16),"SÍ","NO"),IF(G16="Baja",IF(AND(H16<>"",H16<=F16),"SÍ","NO"))))),"") -> SÍ | J16: =IF(B16="","",IFERROR(IF(I16="SÍ",D16*100,0),"")) -> 16
C17: Total porcentaje asignado | D17: =SUM($D$11:$D$16) -> 1 | I17: Puntuación Final | J17: =IF(D17<>1,0,SUM($J$11:$J$16)) -> 100

Sheet Supervis@r_Int9
A1: Unidad Organizativa | C1: =IF(ISBLANK('Supervis@r'!$C$1),"",'Supervis@r'!$C$1) -> SERVICIOS OPERATIVOS | I1: Periodo Evaluado
A2: Programa | C2: =IF(ISBLANK('Supervis@r'!$C$2),"",'Supervis@r'!$C$2) -> ENCARGADOS Y CAPATACES | I2: ='Supervis@r'!$I$2 -> 2025 | J2: ='Supervis@r'!$J$2 -> 2026
A3: Supervisor/a | C3: =IF(ISBLANK('Supervis@r'!$C$3),"",CONCATENATE('Supervis@r'!$C$3," ",'Supervis@r'!$C$4,",",'Supervis@r'!$C$5)) -> JEFE JEFE,JOSE
A5: Puesto evaluado | F5: DNI | H5: ROL | I5: Supervisor/a Intermedio
A6: Apellido1
A7: Apellido2
A8: Nombre
A10: ID | B10: Objetivo (Descripción) | C10: Tipo Objetivo (Individual/Colectivo) | D10: Ponderación / Peso Objetivo (%) | E10: Categoría (Número/Porcentaje) | F10: Umbral (nivel de consecución esperado) | G10: Superación (Alza/Baja) | H10: Resultado Alcanzado | I10: Superación Umbral (SÍ/NO) | J10: Puntuación aportada (0 - 100)
A11: =IF(B11="","",COUNTA($B$11:B11)) -> 1 | B11: Realizar al menos 15 horas de formación "no obligatoria" en el periodo a evaluar, con las consideraciones recogidas en el Reglamento de ED | C11: Individual | D11: 0.2 | E11: Número | F11: 15 | G11: Alza | H11: 15 | I11: =IFERROR(IF(OR(A11="",F11=""),"",IF(AND(G11<>"Alza",G11<>"Baja"),"",IF(G11="Alza",IF(AND(H11<>"",H11>=F11),"SÍ","NO"),IF(G11="Baja",IF(AND(H11<>"",H11<=F11),"SÍ","NO"))))),"") -> SÍ | J11: =IF(B11="","",IFERROR(IF(I11="SÍ",D11*100,0),"")) -> 20
A12: =IF(B12="","",COUNTA($B$11:B12)) -> 2 | B12: Atender y conversar la totalidad de propuestas de mejora presentadas por el equipo en un plazo máximo de 2 meses desde su presentación. | C12: Individual | D12: 0.2 | E12: Número | F12: 1 | G12: Alza | H12: 1 | I12: =IFERROR(IF(OR(A12="",F12=""),"",IF(AND(G12<>"Alza",G12<>"Baja"),"",IF(G12="Alza",IF(AND(H12<>"",H12>=F12),"SÍ","NO"),IF(G12="Baja",IF(AND(H12<>"",H12<=F12),"SÍ","NO"))))),"") -> SÍ | J12: =IF(B12="","",IFERROR(IF(I12="SÍ",D12*100,0),"")) -> 20
A13: =IF(B13="","",COUNTA($B$11:B13)) -> 3 | B13: Desarrollo de dos conversaciones individuales de feedback al año con las personas bajo tu responsabilidad y/o con tu responsable directo para llevar a cabo una valoración mutua del desarrollo de la actividad. | C13: Individual | D13: 0.2 | E13: Número | F13: 2 | G13: Alza | H13: 2 | I13: =IFERROR(IF(OR(A13="",F13=""),"",IF(AND(G13<>"Alza",G13<>"Baja"),"",IF(G13="Alza",IF(AND(H13<>"",H13>=F13),"SÍ","NO"),IF(G13="Baja",IF(AND(H13<>"",H13<=F13),"SÍ","NO"))))),"") -> SÍ | J13: =IF(B13="","",IFERROR(IF(I13="SÍ",D13*100,0),"")) -> 20
A14: =IF(B14="","",COUNTA($B$11:B14)) -> 4 | B14: Presentar los objetivos de desempeño de todo su personal a la Comisión de Garantías de la Evaluación del Desempeño antes del 31 de mayo. | C14: Individual | D14: 0.12 | E14: Número | F14: 1 | G14: Alza | H14: 1 | I14: =IFERROR(IF(OR(A14="",F14=""),"",IF(AND(G14<>"Alza",G14<>"Baja"),"",IF(G14="Alza",IF(AND(H14<>"",H14>=F14),"SÍ","NO"),IF(G14="Baja",IF(AND(H14<>"",H14<=F14),"SÍ","NO"))))),"") -> SÍ | J14: =IF(B14="","",IFERROR(IF(I14="SÍ",D14*100,0),"")) -> 12
A15: =IF(B15="","",COUNTA($B$11:B15)) -> 5 | B15: Presentar el resultado de evaluación de objetivos de desempeño de todo su personal a la Comisión de Garantías de la Evaluación del Desempeño antes del 1 de septiembre. | C15: Individual | D15: 0.12 | E15: Número | F15: 1 | G15: Alza | H15: 1 | I15: =IFERROR(IF(OR(A15="",F15=""),"",IF(AND(G15<>"Alza",G15<>"Baja"),"",IF(G15="Alza",IF(AND(H15<>"",H15>=F15),"SÍ","NO"),IF(G15="Baja",IF(AND(H15<>"",H15<=F15),"SÍ","NO"))))),"") -> SÍ | J15: =IF(B15="","",IFERROR(IF(I15="SÍ",D15*100,0),"")) -> 12
A16: =IF(B16="","",COUNTA($B$11:B16)) -> 6 | B16: Gestión de incidencias presentadas por los Supervisados | C16: Individual | D16: =IF(B16="","",16%) -> 0.16 | E16: Porcentaje | F16: 80 | G16: Alza | H16: 80 | I16: =IFERROR(IF(OR(A16="",F16=""),"",IF(AND(G16<>"Alza",G16<>"Baja"),"",IF(G16="Alza",IF(AND(H16<>"",H16>=F16),"SÍ","NO"),IF(G16="Baja",IF(AND(H16<>"",H16<=F16),"SÍ","NO"))))),"") -> SÍ | J16: =IF(B16="","",IFERROR(IF(I16="SÍ",D16*100,0),"")) -> 16
C17: Total porcentaje asignado | D17: =SUM($D$11:$D$16) -> 1 | I17: Puntuación Final | J17: =IF(D17<>1,0,SUM($J$11:$J$16)) -> 100

Sheet Supervis@r_Int10
A1: Unidad Organizativa | C1: =IF(ISBLANK('Supervis@r'!$C$1),"",'Supervis@r'!$C$1) -> SERVICIOS OPERATIVOS | I1: Periodo Evaluado
A2: Programa | C2: =IF(ISBLANK('Supervis@r'!$C$2),"",'Supervis@r'!$C$2) -> ENCARGADOS Y CAPATACES | I2: ='Supervis@r'!$I$2 -> 2025 | J2: ='Supervis@r'!$J$2 -> 2026
A3: Supervisor/a | C3: =IF(ISBLANK('Supervis@r'!$C$3),"",CONCATENATE('Supervis@r'!$C$3," ",'Supervis@r'!$C$4,",",'Supervis@r'!$C$5)) -> JEFE JEFE,JOSE
A5: Puesto evaluado | F5: DNI | H5: ROL | I5: Supervisor/a Intermedio
A6: Apellido1
A7: Apellido2
A8: Nombre
A10: ID | B10: Objetivo (Descripción) | C10: Tipo Objetivo (Individual/Colectivo) | D10: Ponderación / Peso Objetivo (%) | E10: Categoría (Número/Porcentaje) | F10: Umbral (nivel de consecución esperado) | G10: Superación (Alza/Baja) | H10: Resultado Alcanzado | I10: Superación Umbral (SÍ/NO) | J10: Puntuación aportada (0 - 100)
A11: =IF(B11="","",COUNTA($B$11:B11)) -> 1 | B11: Realizar al menos 15 horas de formación "no obligatoria" en el periodo a evaluar, con las consideraciones recogidas en el Reglamento de ED | C11: Individual | D11: 0.2 | E11: Número | F11: 15 | G11: Alza | H11: 35 | I11: =IFERROR(IF(OR(A11="",F11=""),"",IF(AND(G11<>"Alza",G11<>"Baja"),"",IF(G11="Alza",IF(AND(H11<>"",H11>=F11),"SÍ","NO"),IF(G11="Baja",IF(AND(H11<>"",H11<=F11),"SÍ","NO"))))),"") -> SÍ | J11: =IF(B11="","",IFERROR(IF(I11="SÍ",D11*100,0),"")) -> 20
A12: =IF(B12="","",COUNTA($B$11:B12)) -> 2 | B12: Atender y conversar la totalidad de propuestas de mejora presentadas por el equipo en un plazo máximo de 2 meses desde su presentación. | C12: Individual | D12: 0.2 | E12: Número | F12: 1 | G12: Alza | H12: 1 | I12: =IFERROR(IF(OR(A12="",F12=""),"",IF(AND(G12<>"Alza",G12<>"Baja"),"",IF(G12="Alza",IF(AND(H12<>"",H12>=F12),"SÍ","NO"),IF(G12="Baja",IF(AND(H12<>"",H12<=F12),"SÍ","NO"))))),"") -> SÍ | J12: =IF(B12="","",IFERROR(IF(I12="SÍ",D12*100,0),"")) -> 20
A13: =IF(B13="","",COUNTA($B$11:B13)) -> 3 | B13: Desarrollo de dos conversaciones individuales de feedback al año con las personas bajo tu responsabilidad y/o con tu responsable directo para llevar a cabo una valoración mutua del desarrollo de la actividad. | C13: Individual | D13: 0.2 | E13: Número | F13: 2 | G13: Alza | H13: 2 | I13: =IFERROR(IF(OR(A13="",F13=""),"",IF(AND(G13<>"Alza",G13<>"Baja"),"",IF(G13="Alza",IF(AND(H13<>"",H13>=F13),"SÍ","NO"),IF(G13="Baja",IF(AND(H13<>"",H13<=F13),"SÍ","NO"))))),"") -> SÍ | J13: =IF(B13="","",IFERROR(IF(I13="SÍ",D13*100,0),"")) -> 20
A14: =IF(B14="","",COUNTA($B$11:B14)) -> 4 | B14: Presentar los objetivos de desempeño de todo su personal a la Comisión de Garantías de la Evaluación del Desempeño antes del 31 de mayo. | C14: Individual | D14: 0.12 | E14: Número | F14: 1 | G14: Alza | H14: 1 | I14: =IFERROR(IF(OR(A14="",F14=""),"",IF(AND(G14<>"Alza",G14<>"Baja"),"",IF(G14="Alza",IF(AND(H14<>"",H14>=F14),"SÍ","NO"),IF(G14="Baja",IF(AND(H14<>"",H14<=F14),"SÍ","NO"))))),"") -> SÍ | J14: =IF(B14="","",IFERROR(IF(I14="SÍ",D14*100,0),"")) -> 12
A15: =IF(B15="","",COUNTA($B$11:B15)) -> 5 | B15: Presentar el resultado de evaluación de objetivos de desempeño de todo su personal a la Comisión de Garantías de la Evaluación del Desempeño antes del 1 de septiembre. | C15: Individual | D15: 0.12 | E15: Número | F15: 1 | G15: Alza | H15: 1 | I15: =IFERROR(IF(OR(A15="",F15=""),"",IF(AND(G15<>"Alza",G15<>"Baja"),"",IF(G15="Alza",IF(AND(H15<>"",H15>=F15),"SÍ","NO"),IF(G15="Baja",IF(AND(H15<>"",H15<=F15),"SÍ","NO"))))),"") -> SÍ | J15: =IF(B15="","",IFERROR(IF(I15="SÍ",D15*100,0),"")) -> 12
A16: =IF(B16="","",COUNTA($B$11:B16)) -> 6 | B16: Gestión de incidencias presentadas por los Supervisados | C16: Individual | D16: =IF(B16="","",16%) -> 0.16 | E16: Porcentaje | F16: 80 | G16: Alza | H16: 80 | I16: =IFERROR(IF(OR(A16="",F16=""),"",IF(AND(G16<>"Alza",G16<>"Baja"),"",IF(G16="Alza",IF(AND(H16<>"",H16>=F16),"SÍ","NO"),IF(G16="Baja",IF(AND(H16<>"",H16<=F16),"SÍ","NO"))))),"") -> SÍ | J16: =IF(B16="","",IFERROR(IF(I16="SÍ",D16*100,0),"")) -> 16
C17: Total porcentaje asignado | D17: =SUM($D$11:$D$16) -> 1 | I17: Puntuación Final | J17: =IF(D17<>1,0,SUM($J$11:$J$16)) -> 100

Sheet Supervis@r_Int11
A1: Unidad Organizativa | C1: =IF(ISBLANK('Supervis@r'!$C$1),"",'Supervis@r'!$C$1) -> SERVICIOS OPERATIVOS | I1: Periodo Evaluado
A2: Programa | C2: =IF(ISBLANK('Supervis@r'!$C$2),"",'Supervis@r'!$C$2) -> ENCARGADOS Y CAPATACES | I2: ='Supervis@r'!$I$2 -> 2025 | J2: ='Supervis@r'!$J$2 -> 2026
A3: Supervisor/a | C3: =IF(ISBLANK('Supervis@r'!$C$3),"",CONCATENATE('Supervis@r'!$C$3," ",'Supervis@r'!$C$4,",",'Supervis@r'!$C$5)) -> JEFE JEFE,JOSE
A5: Puesto evaluado | F5: DNI | H5: ROL | I5: Supervisor/a Intermedio
A6: Apellido1
A7: Apellido2
A8: Nombre
A10: ID | B10: Objetivo (Descripción) | C10: Tipo Objetivo (Individual/Colectivo) | D10: Ponderación / Peso Objetivo (%) | E10: Categoría (Número/Porcentaje) | F10: Umbral (nivel de consecución esperado) | G10: Superación (Alza/Baja) | H10: Resultado Alcanzado | I10: Superación Umbral (SÍ/NO) | J10: Puntuación aportada (0 - 100)
A11: =IF(B11="","",COUNTA($B$11:B11)) -> 1 | B11: Realizar al menos 15 horas de formación "no obligatoria" en el periodo a evaluar, con las consideraciones recogidas en el Reglamento de ED | C11: Individual | D11: 0.2 | E11: Número | F11: 15 | G11: Alza | I11: =IFERROR(IF(OR(A11="",F11=""),"",IF(AND(G11<>"Alza",G11<>"Baja"),"",IF(G11="Alza",IF(AND(H11<>"",H11>=F11),"SÍ","NO"),IF(G11="Baja",IF(AND(H11<>"",H11<=F11),"SÍ","NO"))))),"") -> NO | J11: =IF(B11="","",IFERROR(IF(I11="SÍ",D11*100,0),"")) -> 0
A12: =IF(B12="","",COUNTA($B$11:B12)) -> 2 | B12: Atender y conversar la totalidad de propuestas de mejora presentadas por el equipo en un plazo máximo de 2 meses desde su presentación. | C12: Individual | D12: 0.2 | E12: Número | F12: 1 | G12: Alza | I12: =IFERROR(IF(OR(A12="",F12=""),"",IF(AND(G12<>"Alza",G12<>"Baja"),"",IF(G12="Alza",IF(AND(H12<>"",H12>=F12),"SÍ","NO"),IF(G12="Baja",IF(AND(H12<>"",H12<=F12),"SÍ","NO"))))),"") -> NO | J12: =IF(B12="","",IFERROR(IF(I12="SÍ",D12*100,0),"")) -> 0
A13: =IF(B13="","",COUNTA($B$11:B13)) -> 3 | B13: Desarrollo de dos conversaciones individuales de feedback al año con las personas bajo tu responsabilidad y/o con tu responsable directo para llevar a cabo una valoración mutua del desarrollo de la actividad. | C13: Individual | D13: 0.2 | E13: Número | F13: 2 | G13: Alza | I13: =IFERROR(IF(OR(A13="",F13=""),"",IF(AND(G13<>"Alza",G13<>"Baja"),"",IF(G13="Alza",IF(AND(H13<>"",H13>=F13),"SÍ","NO"),IF(G13="Baja",IF(AND(H13<>"",H13<=F13),"SÍ","NO"))))),"") -> NO | J13: =IF(B13="","",IFERROR(IF(I13="SÍ",D13*100,0),"")) -> 0
A14: =IF(B14="","",COUNTA($B$11:B14)) -> 4 | B14: Presentar los objetivos de desempeño de todo su personal a la Comisión de Garantías de la Evaluación del Desempeño antes del 31 de mayo. | C14: Individual | D14: 0.12 | E14: Número | F14: 1 | G14: Alza | I14: =IFERROR(IF(OR(A14="",F14=""),"",IF(AND(G14<>"Alza",G14<>"Baja"),"",IF(G14="Alza",IF(AND(H14<>"",H14>=F14),"SÍ","NO"),IF(G14="Baja",IF(AND(H14<>"",H14<=F14),"SÍ","NO"))))),"") -> NO | J14: =IF(B14="","",IFERROR(IF(I14="SÍ",D14*100,0),"")) -> 0
A15: =IF(B15="","",COUNTA($B$11:B15)) -> 5 | B15: Presentar el resultado de evaluación de objetivos de desempeño de todo su personal a la Comisión de Garantías de la Evaluación del Desempeño antes del 1 de septiembre. | C15: Individual | D15: 0.12 | E15: Número | F15: 1 | G15: Alza | I15: =IFERROR(IF(OR(A15="",F15=""),"",IF(AND(G15<>"Alza",G15<>"Baja"),"",IF(G15="Alza",IF(AND(H15<>"",H15>=F15),"SÍ","NO"),IF(G15="Baja",IF(AND(H15<>"",H15<=F15),"SÍ","NO"))))),"") -> NO | J15: =IF(B15="","",IFERROR(IF(I15="SÍ",D15*100,0),"")) -> 0
A16: =IF(B16="","",COUNTA($B$11:B16)) -> 6 | D16: =IF(B16="","",16%) -> 0.16 | I16: =IFERROR(IF(OR(A16="",F16=""),"",IF(AND(G16<>"Alza",G16<>"Baja"),"",IF(G16="Alza",IF(AND(H16<>"",H16>=F16),"SÍ","NO"),IF(G16="Baja",IF(AND(H16<>"",H16<=F16),"SÍ","NO"))))),"") | J16: =IF(B16="","",IFERROR(IF(I16="SÍ",D16*100,0),"")) -> 0
C17: Total porcentaje asignado | D17: =SUM($D$11:$D$16) -> 1 | I17: Puntuación Final | J17: =IF(D17<>1,0,SUM($J$11:$J$16)) -> 0

Sheet Supervis@r_Int12
A1: Unidad Organizativa | C1: =IF(ISBLANK('Supervis@r'!$C$1),"",'Supervis@r'!$C$1) -> SERVICIOS OPERATIVOS | I1: Periodo Evaluado
A2: Programa | C2: =IF(ISBLANK('Supervis@r'!$C$2),"",'Supervis@r'!$C$2) -> ENCARGADOS Y CAPATACES | I2: ='Supervis@r'!$I$2 -> 2025 | J2: ='Supervis@r'!$J$2 -> 2026
A3: Supervisor/a | C3: =IF(ISBLANK('Supervis@r'!$C$3),"",CONCATENATE('Supervis@r'!$C$3," ",'Supervis@r'!$C$4,",",'Supervis@r'!$C$5)) -> JEFE JEFE,JOSE
A5: Puesto evaluado | F5: DNI | H5: ROL | I5: Supervisor/a Intermedio
A6: Apellido1
A7: Apellido2
A8: Nombre
A10: ID | B10: Objetivo (Descripción) | C10: Tipo Objetivo (Individual/Colectivo) | D10: Ponderación / Peso Objetivo (%) | E10: Categoría (Número/Porcentaje) | F10: Umbral (nivel de consecución esperado) | G10: Superación (Alza/Baja) | H10: Resultado Alcanzado | I10: Superación Umbral (SÍ/NO) | J10: Puntuación aportada (0 - 100)
A11: =IF(B11="","",COUNTA($B$11:B11)) -> 1 | B11: Realizar al menos 15 horas de formación "no obligatoria" en el periodo a evaluar, con las consideraciones recogidas en el Reglamento de ED | C11: Individual | D11: 0.2 | E11: Número | F11: 15 | G11: Alza | I11: =IFERROR(IF(OR(A11="",F11=""),"",IF(AND(G11<>"Alza",G11<>"Baja"),"",IF(G11="Alza",IF(AND(H11<>"",H11>=F11),"SÍ","NO"),IF(G11="Baja",IF(AND(H11<>"",H11<=F11),"SÍ","NO"))))),"") -> NO | J11: =IF(B11="","",IFERROR(IF(I11="SÍ",D11*100,0),"")) -> 0
A12: =IF(B12="","",COUNTA($B$11:B12)) -> 2 | B12: Atender y conversar la totalidad de propuestas de mejora presentadas por el equipo en un plazo máximo de 2 meses desde su presentación. | C12: Individual | D12: 0.2 | E12: Número | F12: 1 | G12: Alza | I12: =IFERROR(IF(OR(A12="",F12=""),"",IF(AND(G12<>"Alza",G12<>"Baja"),"",IF(G12="Alza",IF(AND(H12<>"",H12>=F12),"SÍ","NO"),IF(G12="Baja",IF(AND(H12<>"",H12<=F12),"SÍ","NO"))))),"") -> NO | J12: =IF(B12="","",IFERROR(IF(I12="SÍ",D12*100,0),"")) -> 0
