Workbook

Sheet Instrucciones
B38: Nota: Valor de la Ponderación / Peso Objetivo (%): | P38: Nota: Valor de la Ponderación / Peso Objetivo (%):
B39:  El rango de los objetivos está entre 10 y 40. | P39:  El rango de los objetivos está entre 10 y 40.
B40:   Total porcentaje = 100% | P40:   Total porcentaje = 100%
B77: Nota: Valor de la Ponderación / Peso Objetivo (%):
B78:  El rango de los objetivos está entre 10 y 40.
B79:   Total porcentaje = 100%
T81: Antes de guardar como PDF o imprimir, filtrar y desmarcar las vacías.

Sheet RESULTADOS_OBJETIVOS
A1: Periodo Evaluado | C1: Programa | D1: =IF(ISBLANK('Supervis@r1'!$C$2),"",'Supervis@r1'!$C$2) -> ADMINISTRACION
A2: =CONCATENATE('Supervis@r1'!$I$2,"-",'Supervis@r1'!$J$2) -> 2025-2026 | C2: Supervisor/a | D2: =IF(ISBLANK('Supervis@r1'!$C$3),"",CONCATENATE('Supervis@r1'!$C$3," ",'Supervis@r1'!$C$4,",",'Supervis@r1'!$C$5)) -> JEFE JEFE,JOSE
A4: Ir a la hoja de cálculo número | B4: DNI | C4: Apellido1 | D4: Apellido2 | E4: Nombre | F4: Puntuación aportada (0 - 100) | G4: ROL | H4: BOLSA DEL PROGRAMA (en caso de participación)
A5: 1 | B5: =IF(ISBLANK('Supervis@r1'!G7),"",'Supervis@r1'!G7) -> 23456789B | C5: =IF(ISBLANK('Supervis@r1'!$C$3),"",'Supervis@r1'!$C$3) -> JEFE | D5: =IF(ISBLANK('Supervis@r1'!$C$4),"",'Supervis@r1'!$C$4) -> JEFE | E5: =IF(ISBLANK('Supervis@r1'!$C$5),"",'Supervis@r1'!$C$5) -> JOSE | F5: =IF(ISBLANK('Supervis@r1'!$G$7),"",'Supervis@r1'!$J$19) -> 0 | G5: =IF(B5="","","Supervisor/a") -> Supervisor/a | H5: =IF(B5="","",IF(F5>=0,IF(F5<70,"NO RECIBE BOLSA","RECIBE BOLSA"),"")) -> NO RECIBE BOLSA
A6: 2 | B6: =IF(ISBLANK('Supervis@r1_Int'!$G$5),"",'Supervis@r1_Int'!G5) | C6: =IF(ISBLANK('Supervis@r1_Int'!$C$6),"",'Supervis@r1_Int'!$C$6) | D6: =IF(ISBLANK('Supervis@r1_Int'!$C$7),"",'Supervis@r1_Int'!$C$7) | E6: =IF(ISBLANK('Supervis@r1_Int'!$C$8),"",'Supervis@r1_Int'!$C$8) | F6: =IF(ISBLANK('Supervis@r1_Int'!G5),"",'Supervis@r1_Int'!J17) | G6: =IF(B6="","","Supervisor/a Intermedio") | H6: =IF(B6="","",IF(F6>=0,IF(F6<70,"NO RECIBE BOLSA","RECIBE BOLSA"),""))
A7: 3 | B7: =IF(ISBLANK('Colaborad@r1'!$G$6),"",'Colaborad@r1'!$G$6) -> 12345670C | C7: =IF(ISBLANK('Colaborad@r1'!$C$7),"",'Colaborad@r1'!$C$7) -> ALGUIEN | D7: =IF(ISBLANK('Colaborad@r1'!$C$8),"",'Colaborad@r1'!$C$8) -> ALGUIEN | E7: =IF(ISBLANK('Colaborad@r1'!$C$9),"",'Colaborad@r1'!$C$9) -> MANUEL | F7: =IF(ISBLANK('Colaborad@r1'!$G$6),"",'Colaborad@r1'!$J$19) -> 100 | G7: =IF(B7="","","Colaborador/a") -> Colaborador/a | H7: =IF(B7="","",IF(F7>=0,IF(F7<70,"NO RECIBE BOLSA","RECIBE BOLSA"),"")) -> RECIBE BOLSA
A8: 4 | B8: =IF(ISBLANK('Colaborad@r2'!$G$6),"",'Colaborad@r2'!$G$6) -> 12345679B | C8: =IF(ISBLANK('Colaborad@r2'!$C$7),"",'Colaborad@r2'!$C$7) -> NADIE | D8: =IF(ISBLANK('Colaborad@r2'!$C$8),"",'Colaborad@r2'!$C$8) -> NADIE | E8: =IF(ISBLANK('Colaborad@r2'!$C$9),"",'Colaborad@r2'!$C$9) -> MARIA | F8: =IF(ISBLANK('Colaborad@r2'!$G$6),"",'Colaborad@r2'!$J$19) -> 0 | G8: =IF(B8="","","Colaborador/a") -> Colaborador/a | H8: =IF(B8="","",IF(F8>=0,IF(F8<70,"NO RECIBE BOLSA","RECIBE BOLSA"),"")) -> NO RECIBE BOLSA
A9: 5 | B9: =IF(ISBLANK('Colaborad@r3'!$G$6),"",'Colaborad@r3'!$G$6) -> 12345678A | C9: =IF(ISBLANK('Colaborad@r3'!$C$7),"",'Colaborad@r3'!$C$7) -> EJEMPLO | D9: =IF(ISBLANK('Colaborad@r3'!$C$8),"",'Colaborad@r3'!$C$8) -> EJEMPLO | E9: =IF(ISBLANK('Colaborad@r3'!$C$9),"",'Colaborad@r3'!$C$9) -> JUAN | F9: =IF(ISBLANK('Colaborad@r3'!$G$6),"",'Colaborad@r3'!$J$19) -> 100 | G9: =IF(B9="","","Colaborador/a") -> Colaborador/a | H9: =IF(B9="","",IF(F9>=0,IF(F9<70,"NO RECIBE BOLSA","RECIBE BOLSA"),"")) -> RECIBE BOLSA
A10: 6 | B10: =IF(ISBLANK('Colaborad@r4'!$G$6),"",'Colaborad@r4'!$G$6) | C10: =IF(ISBLANK('Colaborad@r4'!$C$7),"",'Colaborad@r4'!$C$7) | D10: =IF(ISBLANK('Colaborad@r4'!$C$8),"",'Colaborad@r4'!$C$8) | E10: =IF(ISBLANK('Colaborad@r4'!$C$9),"",'Colaborad@r4'!$C$9) | F10: =IF(ISBLANK('Colaborad@r4'!$G$6),"",'Colaborad@r4'!$J$19) | G10: =IF(B10="","","Colaborador/a") | H10: =IF(B10="","",IF(F10>=0,IF(F10<70,"NO RECIBE BOLSA","RECIBE BOLSA"),""))
A11: 7 | B11: =IF(ISBLANK('Colaborad@r5'!$G$6),"",'Colaborad@r5'!$G$6) | C11: =IF(ISBLANK('Colaborad@r5'!$C$7),"",'Colaborad@r5'!$C$7) | D11: =IF(ISBLANK('Colaborad@r5'!$C$8),"",'Colaborad@r5'!$C$8) | E11: =IF(ISBLANK('Colaborad@r5'!$C$9),"",'Colaborad@r5'!$C$9) | F11: =IF(ISBLANK('Colaborad@r5'!$G$6),"",'Colaborad@r5'!$J$19) | G11: =IF(B11="","","Colaborador/a") | H11: =IF(B11="","",IF(F11>=0,IF(F11<70,"NO RECIBE BOLSA","RECIBE BOLSA"),""))
A12: 8 | B12: =IF(ISBLANK('Colaborad@r6'!$G$6),"",'Colaborad@r6'!$G$6) | C12: =IF(ISBLANK('Colaborad@r6'!$C$7),"",'Colaborad@r6'!$C$7) | D12: =IF(ISBLANK('Colaborad@r6'!$C$8),"",'Colaborad@r6'!$C$8) | E12: =IF(ISBLANK('Colaborad@r6'!$C$9),"",'Colaborad@r6'!$C$9) | F12: =IF(ISBLANK('Colaborad@r6'!$G$6),"",'Colaborad@r6'!$J$19) | G12: =IF(B12="","","Colaborador/a") | H12: =IF(B12="","",IF(F12>=0,IF(F12<70,"NO RECIBE BOLSA","RECIBE BOLSA"),""))
A13: 9 | B13: =IF(ISBLANK('Colaborad@r7'!$G$6),"",'Colaborad@r7'!$G$6) | C13: =IF(ISBLANK('Colaborad@r7'!$C$7),"",'Colaborad@r7'!$C$7) | D13: =IF(ISBLANK('Colaborad@r7'!$C$8),"",'Colaborad@r7'!$C$8) | E13: =IF(ISBLANK('Colaborad@r7'!$C$9),"",'Colaborad@r7'!$C$9) | F13: =IF(ISBLANK('Colaborad@r7'!$G$6),"",'Colaborad@r7'!$J$19) | G13: =IF(B13="","","Colaborador/a") | H13: =IF(B13="","",IF(F13>=0,IF(F13<70,"NO RECIBE BOLSA","RECIBE BOLSA"),""))
A14: 10 | B14: =IF(ISBLANK('Colaborad@r8'!$G$6),"",'Colaborad@r8'!$G$6) | C14: =IF(ISBLANK('Colaborad@r8'!$C$7),"",'Colaborad@r8'!$C$7) | D14: =IF(ISBLANK('Colaborad@r8'!$C$8),"",'Colaborad@r8'!$C$8) | E14: =IF(ISBLANK('Colaborad@r8'!$C$9),"",'Colaborad@r8'!$C$9) | F14: =IF(ISBLANK('Colaborad@r8'!$G$6),"",'Colaborad@r8'!$J$19) | G14: =IF(B14="","","Colaborador/a") | H14: =IF(B14="","",IF(F14>=0,IF(F14<70,"NO RECIBE BOLSA","RECIBE BOLSA"),""))
A15: 11 | B15: =IF(ISBLANK('Colaborad@r9'!$G$6),"",'Colaborad@r9'!$G$6) | C15: =IF(ISBLANK('Colaborad@r9'!$C$7),"",'Colaborad@r9'!$C$7) | D15: =IF(ISBLANK('Colaborad@r9'!$C$8),"",'Colaborad@r9'!$C$8) | E15: =IF(ISBLANK('Colaborad@r9'!$C$9),"",'Colaborad@r9'!$C$9) | F15: =IF(ISBLANK('Colaborad@r9'!$G$6),"",'Colaborad@r9'!$J$19) | G15: =IF(B15="","","Colaborador/a") | H15: =IF(B15="","",IF(F15>=0,IF(F15<70,"NO RECIBE BOLSA","RECIBE BOLSA"),""))
A16: 12 | B16: =IF(ISBLANK('Colaborad@r10'!$G$6),"",'Colaborad@r10'!$G$6) | C16: =IF(ISBLANK('Colaborad@r10'!$C$7),"",'Colaborad@r10'!$C$7) | D16: =IF(ISBLANK('Colaborad@r10'!$C$8),"",'Colaborad@r10'!$C$8) | E16: =IF(ISBLANK('Colaborad@r10'!$C$9),"",'Colaborad@r10'!$C$9) | F16: =IF(ISBLANK('Colaborad@r10'!$G$6),"",'Colaborad@r11'!$J$19) | G16: =IF(B16="","","Colaborador/a") | H16: =IF(B16="","",IF(F16>=0,IF(F16<70,"NO RECIBE BOLSA","RECIBE BOLSA"),""))
A17: 13 | B17: =IF(ISBLANK('Colaborad@r11'!$G$6),"",'Colaborad@r11'!$G$6) | C17: =IF(ISBLANK('Colaborad@r11'!$C$7),"",'Colaborad@r11'!$C$7) | D17: =IF(ISBLANK('Colaborad@r11'!$C$8),"",'Colaborad@r11'!$C$8) | E17: =IF(ISBLANK('Colaborad@r11'!$C$9),"",'Colaborad@r11'!$C$9) | F17: =IF(ISBLANK('Colaborad@r11'!$G$6),"",'Colaborad@r11'!$J$19) | G17: =IF(B17="","","Colaborador/a") | H17: =IF(B17="","",IF(F17>=0,IF(F17<70,"NO RECIBE BOLSA","RECIBE BOLSA"),""))
A18: 14 | B18: =IF(ISBLANK('Colaborad@r12'!$G$6),"",'Colaborad@r12'!$G$6) | C18: =IF(ISBLANK('Colaborad@r12'!$C$7),"",'Colaborad@r12'!$C$7) | D18: =IF(ISBLANK('Colaborad@r12'!$C$8),"",'Colaborad@r12'!$C$8) | E18: =IF(ISBLANK('Colaborad@r12'!$C$9),"",'Colaborad@r12'!$C$9) | F18: =IF(ISBLANK('Colaborad@r12'!$G$6),"",'Colaborad@r12'!$J$19) | G18: =IF(B18="","","Colaborador/a") | H18: =IF(B18="","",IF(F18>=0,IF(F18<70,"NO RECIBE BOLSA","RECIBE BOLSA"),""))
A19: 15 | B19: =IF(ISBLANK('Colaborad@r13'!$G$6),"",'Colaborad@r13'!$G$6) | C19: =IF(ISBLANK('Colaborad@r13'!$C$7),"",'Colaborad@r13'!$C$7) | D19: =IF(ISBLANK('Colaborad@r13'!$C$8),"",'Colaborad@r13'!$C$8) | E19: =IF(ISBLANK('Colaborad@r13'!$C$9),"",'Colaborad@r13'!$C$9) | F19: =IF(ISBLANK('Colaborad@r13'!$G$6),"",'Colaborad@r13'!$J$19) | G19: =IF(B19="","","Colaborador/a") | H19: =IF(B19="","",IF(F19>=0,IF(F19<70,"NO RECIBE BOLSA","RECIBE BOLSA"),""))
A20: 16 | B20: =IF(ISBLANK('Colaborad@r14'!$G$6),"",'Colaborad@r14'!$G$6) | C20: =IF(ISBLANK('Colaborad@r14'!$C$7),"",'Colaborad@r14'!$C$7) | D20: =IF(ISBLANK('Colaborad@r14'!$C$8),"",'Colaborad@r14'!$C$8) | E20: =IF(ISBLANK('Colaborad@r14'!$C$9),"",'Colaborad@r14'!$C$9) | F20: =IF(ISBLANK('Colaborad@r14'!$G$6),"",'Colaborad@r14'!$J$19) | G20: =IF(B20="","","Colaborador/a") | H20: =IF(B20="","",IF(F20>=0,IF(F20<70,"NO RECIBE BOLSA","RECIBE BOLSA"),""))
A21: 17 | B21: =IF(ISBLANK('Colaborad@r15'!$G$6),"",'Colaborad@r15'!$G$6) | C21: =IF(ISBLANK('Colaborad@r15'!$C$7),"",'Colaborad@r15'!$C$7) | D21: =IF(ISBLANK('Colaborad@r15'!$C$8),"",'Colaborad@r15'!$C$8) | E21: =IF(ISBLANK('Colaborad@r15'!$C$9),"",'Colaborad@r15'!$C$9) | F21: =IF(ISBLANK('Colaborad@r15'!$G$6),"",'Colaborad@r15'!$J$19) | G21: =IF(B21="","","Colaborador/a") | H21: =IF(B21="","",IF(F21>=0,IF(F21<70,"NO RECIBE BOLSA","RECIBE BOLSA"),""))
A22: 18 | B22: =IF(ISBLANK('Colaborad@r16'!$G$6),"",'Colaborad@r16'!$G$6) | C22: =IF(ISBLANK('Colaborad@r16'!$C$7),"",'Colaborad@r16'!$C$7) | D22: =IF(ISBLANK('Colaborad@r16'!$C$8),"",'Colaborad@r16'!$C$8) | E22: =IF(ISBLANK('Colaborad@r16'!$C$9),"",'Colaborad@r16'!$C$9) | F22: =IF(ISBLANK('Colaborad@r16'!$G$6),"",'Colaborad@r16'!$J$19) | G22: =IF(B22="","","Colaborador/a") | H22: =IF(B22="","",IF(F22>=0,IF(F22<70,"NO RECIBE BOLSA","RECIBE BOLSA"),""))
A23: 19 | B23: =IF(ISBLANK('Colaborad@r17'!$G$6),"",'Colaborad@r17'!$G$6) | C23: =IF(ISBLANK('Colaborad@r17'!$C$7),"",'Colaborad@r17'!$C$7) | D23: =IF(ISBLANK('Colaborad@r17'!$C$8),"",'Colaborad@r17'!$C$8) | E23: =IF(ISBLANK('Colaborad@r17'!$C$9),"",'Colaborad@r17'!$C$9) | F23: =IF(ISBLANK('Colaborad@r17'!$G$6),"",'Colaborad@r17'!$J$19) | G23: =IF(B23="","","Colaborador/a") | H23: =IF(B23="","",IF(F23>=0,IF(F23<70,"NO RECIBE BOLSA","RECIBE BOLSA"),""))
A24: 20 | B24: =IF(ISBLANK('Colaborad@r18'!$G$6),"",'Colaborad@r18'!$G$6) | C24: =IF(ISBLANK('Colaborad@r18'!$C$7),"",'Colaborad@r18'!$C$7) | D24: =IF(ISBLANK('Colaborad@r18'!$C$8),"",'Colaborad@r18'!$C$8) | E24: =IF(ISBLANK('Colaborad@r18'!$C$9),"",'Colaborad@r18'!$C$9) | F24: =IF(ISBLANK('Colaborad@r18'!$G$6),"",'Colaborad@r18'!$J$19) | G24: =IF(B24="","","Colaborador/a") | H24: =IF(B24="","",IF(F24>=0,IF(F24<70,"NO RECIBE BOLSA","RECIBE BOLSA"),""))
A25: 21 | B25: =IF(ISBLANK('Colaborad@r19'!$G$6),"",'Colaborad@r19'!$G$6) | C25: =IF(ISBLANK('Colaborad@r19'!$C$7),"",'Colaborad@r19'!$C$7) | D25: =IF(ISBLANK('Colaborad@r19'!$C$8),"",'Colaborad@r19'!$C$8) | E25: =IF(ISBLANK('Colaborad@r19'!$C$9),"",'Colaborad@r19'!$C$9) | F25: =IF(ISBLANK('Colaborad@r19'!$G$6),"",'Colaborad@r19'!$J$19) | G25: =IF(B25="","","Colaborador/a") | H25: =IF(B25="","",IF(F25>=0,IF(F25<70,"NO RECIBE BOLSA","RECIBE BOLSA"),""))
A26: 22 | B26: =IF(ISBLANK('Colaborad@r20'!$G$6),"",'Colaborad@r20'!$G$6) | C26: =IF(ISBLANK('Colaborad@r20'!$C$7),"",'Colaborad@r20'!$C$7) | D26: =IF(ISBLANK('Colaborad@r20'!$C$8),"",'Colaborad@r20'!$C$8) | E26: =IF(ISBLANK('Colaborad@r20'!$C$9),"",'Colaborad@r20'!$C$9) | F26: =IF(ISBLANK('Colaborad@r20'!$G$6),"",'Colaborad@r20'!$J$19) | G26: =IF(B26="","","Colaborador/a") | H26: =IF(B26="","",IF(F26>=0,IF(F26<70,"NO RECIBE BOLSA","RECIBE BOLSA"),""))
A27: 23 | B27: =IF(ISBLANK('Colaborad@r21'!$G$6),"",'Colaborad@r21'!$G$6) | C27: =IF(ISBLANK('Colaborad@r21'!$C$7),"",'Colaborad@r21'!$C$7) | D27: =IF(ISBLANK('Colaborad@r21'!$C$8),"",'Colaborad@r21'!$C$8) | E27: =IF(ISBLANK('Colaborad@r21'!$C$9),"",'Colaborad@r21'!$C$9) | F27: =IF(ISBLANK('Colaborad@r21'!$G$6),"",'Colaborad@r21'!$J$19) | G27: =IF(B27="","","Colaborador/a") | H27: =IF(B27="","",IF(F27>=0,IF(F27<70,"NO RECIBE BOLSA","RECIBE BOLSA"),""))
A28: 24 | B28: =IF(ISBLANK('Colaborad@r22'!$G$6),"",'Colaborad@r22'!$G$6) | C28: =IF(ISBLANK('Colaborad@r22'!$C$7),"",'Colaborad@r22'!$C$7) | D28: =IF(ISBLANK('Colaborad@r22'!$C$8),"",'Colaborad@r22'!$C$8) | E28: =IF(ISBLANK('Colaborad@r22'!$C$9),"",'Colaborad@r22'!$C$9) | F28: =IF(ISBLANK('Colaborad@r22'!$G$6),"",'Colaborad@r22'!$J$19) | G28: =IF(B28="","","Colaborador/a") | H28: =IF(B28="","",IF(F28>=0,IF(F28<70,"NO RECIBE BOLSA","RECIBE BOLSA"),""))
A29: 25 | B29: =IF(ISBLANK('Colaborad@r23'!$G$6),"",'Colaborad@r23'!$G$6) | C29: =IF(ISBLANK('Colaborad@r23'!$C$7),"",'Colaborad@r23'!$C$7) | D29: =IF(ISBLANK('Colaborad@r23'!$C$8),"",'Colaborad@r23'!$C$8) | E29: =IF(ISBLANK('Colaborad@r23'!$C$9),"",'Colaborad@r23'!$C$9) | F29: =IF(ISBLANK('Colaborad@r23'!$G$6),"",'Colaborad@r23'!$J$19) | G29: =IF(B29="","","Colaborador/a") | H29: =IF(B29="","",IF(F29>=0,IF(F29<70,"NO RECIBE BOLSA","RECIBE BOLSA"),""))
A30: 26 | B30: =IF(ISBLANK('Colaborad@r24'!$G$6),"",'Colaborad@r24'!$G$6) | C30: =IF(ISBLANK('Colaborad@r24'!$C$7),"",'Colaborad@r24'!$C$7) | D30: =IF(ISBLANK('Colaborad@r24'!$C$8),"",'Colaborad@r24'!$C$8) | E30: =IF(ISBLANK('Colaborad@r24'!$C$9),"",'Colaborad@r24'!$C$9) | F30: =IF(ISBLANK('Colaborad@r24'!$G$6),"",'Colaborad@r24'!$J$19) | G30: =IF(B30="","","Colaborador/a") | H30: =IF(B30="","",IF(F30>=0,IF(F30<70,"NO RECIBE BOLSA","RECIBE BOLSA"),""))
A31: 27 | B31: =IF(ISBLANK('Colaborad@r25'!$G$6),"",'Colaborad@r25'!$G$6) | C31: =IF(ISBLANK('Colaborad@r25'!$C$7),"",'Colaborad@r25'!$C$7) | D31: =IF(ISBLANK('Colaborad@r25'!$C$8),"",'Colaborad@r25'!$C$8) | E31: =IF(ISBLANK('Colaborad@r25'!$C$9),"",'Colaborad@r25'!$C$9) | F31: =IF(ISBLANK('Colaborad@r25'!$G$6),"",'Colaborad@r25'!$J$19) | G31: =IF(B31="","","Colaborador/a") | H31: =IF(B31="","",IF(F31>=0,IF(F31<70,"NO RECIBE BOLSA","RECIBE BOLSA"),""))
A32: 28 | B32: =IF(ISBLANK('Colaborad@r26'!$G$6),"",'Colaborad@r26'!$G$6) | C32: =IF(ISBLANK('Colaborad@r26'!$C$7),"",'Colaborad@r26'!$C$7) | D32: =IF(ISBLANK('Colaborad@r26'!$C$8),"",'Colaborad@r26'!$C$8) | E32: =IF(ISBLANK('Colaborad@r26'!$C$9),"",'Colaborad@r26'!$C$9) | F32: =IF(ISBLANK('Colaborad@r26'!$G$6),"",'Colaborad@r26'!$J$19) | G32: =IF(B32="","","Colaborador/a") | H32: =IF(B32="","",IF(F32>=0,IF(F32<70,"NO RECIBE BOLSA","RECIBE BOLSA"),""))
A33: 29 | B33: =IF(ISBLANK('Colaborad@r27'!$G$6),"",'Colaborad@r27'!$G$6) | C33: =IF(ISBLANK('Colaborad@r27'!$C$7),"",'Colaborad@r27'!$C$7) | D33: =IF(ISBLANK('Colaborad@r27'!$C$8),"",'Colaborad@r27'!$C$8) | E33: =IF(ISBLANK('Colaborad@r27'!$C$9),"",'Colaborad@r27'!$C$9) | F33: =IF(ISBLANK('Colaborad@r27'!$G$6),"",'Colaborad@r27'!$J$19) | G33: =IF(B33="","","Colaborador/a") | H33: =IF(B33="","",IF(F33>=0,IF(F33<70,"NO RECIBE BOLSA","RECIBE BOLSA"),""))
A34: 30 | B34: =IF(ISBLANK('Colaborad@r28'!$G$6),"",'Colaborad@r28'!$G$6) | C34: =IF(ISBLANK('Colaborad@r28'!$C$7),"",'Colaborad@r28'!$C$7) | D34: =IF(ISBLANK('Colaborad@r28'!$C$8),"",'Colaborad@r28'!$C$8) | E34: =IF(ISBLANK('Colaborad@r28'!$C$9),"",'Colaborad@r28'!$C$9) | F34: =IF(ISBLANK('Colaborad@r28'!$G$6),"",'Colaborad@r28'!$J$19) | G34: =IF(B34="","","Colaborador/a") | H34: =IF(B34="","",IF(F34>=0,IF(F34<70,"NO RECIBE BOLSA","RECIBE BOLSA"),""))
A35: 31 | B35: =IF(ISBLANK('Colaborad@r29'!$G$6),"",'Colaborad@r29'!$G$6) | C35: =IF(ISBLANK('Colaborad@r29'!$C$7),"",'Colaborad@r29'!$C$7) | D35: =IF(ISBLANK('Colaborad@r29'!$C$8),"",'Colaborad@r29'!$C$8) | E35: =IF(ISBLANK('Colaborad@r29'!$C$9),"",'Colaborad@r29'!$C$9) | F35: =IF(ISBLANK('Colaborad@r29'!$G$6),"",'Colaborad@r29'!$J$19) | G35: =IF(B35="","","Colaborador/a") | H35: =IF(B35="","",IF(F35>=0,IF(F35<70,"NO RECIBE BOLSA","RECIBE BOLSA"),""))
A36: 32 | B36: =IF(ISBLANK('Colaborad@r30'!$G$6),"",'Colaborad@r30'!$G$6) | C36: =IF(ISBLANK('Colaborad@r30'!$C$7),"",'Colaborad@r30'!$C$7) | D36: =IF(ISBLANK('Colaborad@r30'!$C$8),"",'Colaborad@r30'!$C$8) | E36: =IF(ISBLANK('Colaborad@r30'!$C$9),"",'Colaborad@r30'!$C$9) | F36: =IF(ISBLANK('Colaborad@r30'!$G$6),"",'Colaborad@r30'!$J$19) | G36: =IF(B36="","","Colaborador/a") | H36: =IF(B36="","",IF(F36>=0,IF(F36<70,"NO RECIBE BOLSA","RECIBE BOLSA"),""))
A37: 33 | B37: =IF(ISBLANK('Colaborad@r31'!$G$6),"",'Colaborad@r31'!$G$6) | C37: =IF(ISBLANK('Colaborad@r31'!$C$7),"",'Colaborad@r31'!$C$7) | D37: =IF(ISBLANK('Colaborad@r31'!$C$8),"",'Colaborad@r31'!$C$8) | E37: =IF(ISBLANK('Colaborad@r31'!$C$9),"",'Colaborad@r31'!$C$9) | F37: =IF(ISBLANK('Colaborad@r31'!$G$6),"",'Colaborad@r31'!$J$19) | G37: =IF(B37="","","Colaborador/a") | H37: =IF(B37="","",IF(F37>=0,IF(F37<70,"NO RECIBE BOLSA","RECIBE BOLSA"),""))
A38: 34 | B38: =IF(ISBLANK('Colaborad@r32'!$G$6),"",'Colaborad@r32'!$G$6) | C38: =IF(ISBLANK('Colaborad@r32'!$C$7),"",'Colaborad@r32'!$C$7) | D38: =IF(ISBLANK('Colaborad@r32'!$C$8),"",'Colaborad@r32'!$C$8) | E38: =IF(ISBLANK('Colaborad@r32'!$C$9),"",'Colaborad@r32'!$C$9) | F38: =IF(ISBLANK('Colaborad@r32'!$G$6),"",'Colaborad@r32'!$J$19) | G38: =IF(B38="","","Colaborador/a") | H38: =IF(B38="","",IF(F38>=0,IF(F38<70,"NO RECIBE BOLSA","RECIBE BOLSA"),""))
A39: 35 | B39: =IF(ISBLANK('Colaborad@r33'!$G$6),"",'Colaborad@r33'!$G$6) | C39: =IF(ISBLANK('Colaborad@r33'!$C$7),"",'Colaborad@r33'!$C$7) | D39: =IF(ISBLANK('Colaborad@r33'!$C$8),"",'Colaborad@r33'!$C$8) | E39: =IF(ISBLANK('Colaborad@r33'!$C$9),"",'Colaborad@r33'!$C$9) | F39: =IF(ISBLANK('Colaborad@r33'!$G$6),"",'Colaborad@r33'!$J$19) | G39: =IF(B39="","","Colaborador/a") | H39: =IF(B39="","",IF(F39>=0,IF(F39<70,"NO RECIBE BOLSA","RECIBE BOLSA"),""))
A40: 36 | B40: =IF(ISBLANK('Colaborad@r34'!$G$6),"",'Colaborad@r34'!$G$6) | C40: =IF(ISBLANK('Colaborad@r34'!$C$7),"",'Colaborad@r34'!$C$7) | D40: =IF(ISBLANK('Colaborad@r34'!$C$8),"",'Colaborad@r34'!$C$8) | E40: =IF(ISBLANK('Colaborad@r34'!$C$9),"",'Colaborad@r34'!$C$9) | F40: =IF(ISBLANK('Colaborad@r34'!$G$6),"",'Colaborad@r34'!$J$19) | G40: =IF(B40="","","Colaborador/a") | H40: =IF(B40="","",IF(F40>=0,IF(F40<70,"NO RECIBE BOLSA","RECIBE BOLSA"),""))
A41: 37 | B41: =IF(ISBLANK('Colaborad@r35'!$G$6),"",'Colaborad@r35'!$G$6) | C41: =IF(ISBLANK('Colaborad@r35'!$C$7),"",'Colaborad@r35'!$C$7) | D41: =IF(ISBLANK('Colaborad@r35'!$C$8),"",'Colaborad@r35'!$C$8) | E41: =IF(ISBLANK('Colaborad@r35'!$C$9),"",'Colaborad@r35'!$C$9) | F41: =IF(ISBLANK('Colaborad@r35'!$G$6),"",'Colaborad@r35'!$J$19) | G41: =IF(B41="","","Colaborador/a") | H41: =IF(B41="","",IF(F41>=0,IF(F41<70,"NO RECIBE BOLSA","RECIBE BOLSA"),""))
...

Sheet Supervis@r1
A1: Unidad Organizativa | C1: SERVICIOS OPERATIVOS | I1: Periodo Evaluado
A2: Programa | C2: ADMINISTRACION | I2: 2025 | J2: =$I$2+1 -> 2026
A3: Apellido1 Supervisor/a | C3: JEFE
A4: Apellido2 Supervisor/a | C4: JEFE
A5: Nombre Supervisor/a | C5: JOSE
A7: Puesto evaluado | C7: ENCARGADO GENERAL | F7: DNI | G7: 23456789B | H7: ROL | I7: Supervisor/a
A8: Apellido1 | C8: =IF(C3="","",C3) -> JEFE
A9: Apellido2 | C9: =IF(C4="","",C4) -> JEFE
A10: Nombre | C10: =IF(C5="","",C5) -> JOSE
A12: ID | B12: Objetivo (Descripción) | C12: Tipo Objetivo (Individual/Colectivo) | D12: Ponderación / Peso Objetivo (%) | E12: Categoría (Número/Porcentaje) | F12: Umbral (nivel de consecución esperado) | G12: Superación (Alza/Baja) | H12: Resultado Alcanzado | I12: Superación Umbral (SÍ/NO) | J12: Puntuación aportada (0 - 100)
A13: =IF(B13="","",COUNTA($B$13:B13)) -> 1 | B13: Realizar al menos 15 horas de formación "no obligatoria" en el periodo a evaluar, con las consideraciones recogidas en el Reglamento de ED | C13: Individual | D13: 0.2 | E13: Número | F13: 15 | G13: Alza | I13: =IFERROR(IF(OR(A13="",F13=""),"",IF(AND(G13<>"Alza",G13<>"Baja"),"",IF(G13="Alza",IF(AND(H13<>"",H13>=F13),"SÍ","NO"),IF(G13="Baja",IF(AND(H13<>"",H13<=F13),"SÍ","NO"))))),"") -> NO | J13: =IF(B13="","",IFERROR(IF(I13="SÍ",D13*100,0),"")) -> 0
A14: =IF(B14="","",COUNTA($B$13:B14)) -> 2 | B14: Atender y conversar la totalidad de propuestas de mejora presentadas por el equipo en un plazo máximo de 2 meses desde su presentación. | C14: Individual | D14: 0.2 | E14: Número | F14: 2 | G14: Alza | I14: =IFERROR(IF(OR(A14="",F14=""),"",IF(AND(G14<>"Alza",G14<>"Baja"),"",IF(G14="Alza",IF(AND(H14<>"",H14>=F14),"SÍ","NO"),IF(G14="Baja",IF(AND(H14<>"",H14<=F14),"SÍ","NO"))))),"") -> NO | J14: =IF(B14="","",IFERROR(IF(I14="SÍ",D14*100,0),"")) -> 0
A15: =IF(B15="","",COUNTA($B$13:B15)) -> 3 | B15: Desarrollo de dos conversaciones individuales de feedback al año con las personas bajo tu responsabilidad y/o con tu responsable directo para llevar a cabo una valoración mutua del desarrollo de la actividad. | C15: Individual | D15: 0.2 | E15: Número | F15: 2 | G15: Alza | I15: =IFERROR(IF(OR(A15="",F15=""),"",IF(AND(G15<>"Alza",G15<>"Baja"),"",IF(G15="Alza",IF(AND(H15<>"",H15>=F15),"SÍ","NO"),IF(G15="Baja",IF(AND(H15<>"",H15<=F15),"SÍ","NO"))))),"") -> NO | J15: =IF(B15="","",IFERROR(IF(I15="SÍ",D15*100,0),"")) -> 0
A16: =IF(B16="","",COUNTA($B$13:B16)) -> 4 | B16: Presentar los objetivos de desempeño de todo su personal a la Comisión de Garantías de la Evaluación del Desempeño antes del 31 de mayo. | C16: Individual | D16: 0.12 | E16: Número | F16: 1 | G16: Alza | I16: =IFERROR(IF(OR(A16="",F16=""),"",IF(AND(G16<>"Alza",G16<>"Baja"),"",IF(G16="Alza",IF(AND(H16<>"",H16>=F16),"SÍ","NO"),IF(G16="Baja",IF(AND(H16<>"",H16<=F16),"SÍ","NO"))))),"") -> NO | J16: =IF(B16="","",IFERROR(IF(I16="SÍ",D16*100,0),"")) -> 0
A17: =IF(B17="","",COUNTA($B$13:B17)) -> 5 | B17: Presentar el resultado de evaluación de objetivos de desempeño de todo su personal a la Comisión de Garantías de la Evaluación del Desempeño antes del 1 de septiembre. | C17: Individual | D17: 0.12 | E17: Número | F17: 1 | G17: Alza | I17: =IFERROR(IF(OR(A17="",F17=""),"",IF(AND(G17<>"Alza",G17<>"Baja"),"",IF(G17="Alza",IF(AND(H17<>"",H17>=F17),"SÍ","NO"),IF(G17="Baja",IF(AND(H17<>"",H17<=F17),"SÍ","NO"))))),"") -> NO | J17: =IF(B17="","",IFERROR(IF(I17="SÍ",D17*100,0),"")) -> 0
A18: =IF(B18="","",COUNTA($B$13:B18)) -> 6 | D18: =IF(B18="","",16%) -> 0.16 | I18: =IFERROR(IF(OR(A18="",F18=""),"",IF(AND(G18<>"Alza",G18<>"Baja"),"",IF(G18="Alza",IF(AND(H18<>"",H18>=F18),"SÍ","NO"),IF(G18="Baja",IF(AND(H18<>"",H18<=F18),"SÍ","NO"))))),"") | J18: =IF(B18="","",IFERROR(IF(I18="SÍ",D18*100,0),"")) -> 0
C19: Total porcentaje asignado | D19: =SUM($D$13:$D$18) -> 1 | I19: Puntuación Final | J19: =IF(D19<>1,0,SUM($J$13:$J$18)) -> 0

Sheet Supervis@r1_Int
A1: Unidad Organizativa | C1: =IF(ISBLANK('Supervis@r1'!$C$1),"",'Supervis@r1'!$C$1) -> SERVICIOS OPERATIVOS | I1: Periodo Evaluado
A2: Programa | C2: =IF(ISBLANK('Supervis@r1'!$C$2),"",'Supervis@r1'!$C$2) -> ADMINISTRACION | I2: ='Supervis@r1'!$I$2 -> 2025 | J2: ='Supervis@r1'!$J$2 -> 2026
A3: Supervisor/a | C3: =IF(ISBLANK('Supervis@r1'!$C$3),"",CONCATENATE('Supervis@r1'!$C$3," ",'Supervis@r1'!$C$4,",",'Supervis@r1'!$C$5)) -> JEFE JEFE,JOSE
A5: Puesto evaluado | F5: DNI | H5: ROL | I5: Supervisor/a Intermedio
A6: Apellido1
A7: Apellido2
A8: Nombre
A10: ID | B10: Objetivo (Descripción) | C10: Tipo Objetivo (Individual/Colectivo) | D10: Ponderación / Peso Objetivo (%) | E10: Categoría (Número/Porcentaje) | F10: Umbral (nivel de consecución esperado) | G10: Superación (Alza/Baja) | H10: Resultado Alcanzado | I10: Superación Umbral (SÍ/NO) | J10: Puntuación aportada (0 - 100)
A11: =IF(B11="","",COUNTA($B$11:B11)) -> 1 | B11: Realizar al menos 15 horas de formación "no obligatoria" en el periodo a evaluar, con las consideraciones recogidas en el Reglamento de ED | C11: Individual | D11: 0.2 | E11: Número | F11: 15 | G11: Alza | I11: =IFERROR(IF(OR(A11="",F11=""),"",IF(AND(G11<>"Alza",G11<>"Baja"),"",IF(G11="Alza",IF(AND(H11<>"",H11>=F11),"SÍ","NO"),IF(G11="Baja",IF(AND(H11<>"",H11<=F11),"SÍ","NO"))))),"") -> NO | J11: =IF(B11="","",IFERROR(IF(I11="SÍ",D11*100,0),"")) -> 0
A12: =IF(B12="","",COUNTA($B$11:B12)) -> 2 | B12: Atender y conversar la totalidad de propuestas de mejora presentadas por el equipo en un plazo máximo de 2 meses desde su presentación. | C12: Individual | D12: 0.2 | E12: Número | F12: 2 | G12: Alza | I12: =IFERROR(IF(OR(A12="",F12=""),"",IF(AND(G12<>"Alza",G12<>"Baja"),"",IF(G12="Alza",IF(AND(H12<>"",H12>=F12),"SÍ","NO"),IF(G12="Baja",IF(AND(H12<>"",H12<=F12),"SÍ","NO"))))),"") -> NO | J12: =IF(B12="","",IFERROR(IF(I12="SÍ",D12*100,0),"")) -> 0
A13: =IF(B13="","",COUNTA($B$11:B13)) -> 3 | B13: Desarrollo de dos conversaciones individuales de feedback al año con las personas bajo tu responsabilidad y/o con tu responsable directo para llevar a cabo una valoración mutua del desarrollo de la actividad. | C13: Individual | D13: 0.2 | E13: Número | F13: 2 | G13: Alza | I13: =IFERROR(IF(OR(A13="",F13=""),"",IF(AND(G13<>"Alza",G13<>"Baja"),"",IF(G13="Alza",IF(AND(H13<>"",H13>=F13),"SÍ","NO"),IF(G13="Baja",IF(AND(H13<>"",H13<=F13),"SÍ","NO"))))),"") -> NO | J13: =IF(B13="","",IFERROR(IF(I13="SÍ",D13*100,0),"")) -> 0
A14: =IF(B14="","",COUNTA($B$11:B14)) -> 4 | B14: Presentar los objetivos de desempeño de todo su personal a la Comisión de Garantías de la Evaluación del Desempeño antes del 31 de mayo. | C14: Individual | D14: 0.12 | E14: Número | F14: 1 | G14: Alza | I14: =IFERROR(IF(OR(A14="",F14=""),"",IF(AND(G14<>"Alza",G14<>"Baja"),"",IF(G14="Alza",IF(AND(H14<>"",H14>=F14),"SÍ","NO"),IF(G14="Baja",IF(AND(H14<>"",H14<=F14),"SÍ","NO"))))),"") -> NO | J14: =IF(B14="","",IFERROR(IF(I14="SÍ",D14*100,0),"")) -> 0
A15: =IF(B15="","",COUNTA($B$11:B15)) -> 5 | B15: Presentar el resultado de evaluación de objetivos de desempeño de todo su personal a la Comisión de Garantías de la Evaluación del Desempeño antes del 1 de septiembre. | C15: Individual | D15: 0.12 | E15: Número | F15: 1 | G15: Alza | I15: =IFERROR(IF(OR(A15="",F15=""),"",IF(AND(G15<>"Alza",G15<>"Baja"),"",IF(G15="Alza",IF(AND(H15<>"",H15>=F15),"SÍ","NO"),IF(G15="Baja",IF(AND(H15<>"",H15<=F15),"SÍ","NO"))))),"") -> NO | J15: =IF(B15="","",IFERROR(IF(I15="SÍ",D15*100,0),"")) -> 0
A16: =IF(B16="","",COUNTA($B$11:B16)) -> 6 | D16: =IF(B16="","",16%) -> 0.16 | I16: =IFERROR(IF(OR(A16="",F16=""),"",IF(AND(G16<>"Alza",G16<>"Baja"),"",IF(G16="Alza",IF(AND(H16<>"",H16>=F16),"SÍ","NO"),IF(G16="Baja",IF(AND(H16<>"",H16<=F16),"SÍ","NO"))))),"") | J16: =IF(B16="","",IFERROR(IF(I16="SÍ",D16*100,0),"")) -> 0
C17: Total porcentaje asignado | D17: =SUM($D$11:$D$16) -> 1 | I17: Puntuación Final | J17: =IF(D17<>1,0,SUM($J$11:$J$16)) -> 0

Sheet Colaborad@r1
A1: Unidad Organizativa | C1: =IF(ISBLANK('Supervis@r1'!$C$1),"",'Supervis@r1'!$C$1) -> SERVICIOS OPERATIVOS | I1: Periodo Evaluado
A2: Programa | C2: =IF(ISBLANK('Supervis@r1'!$C$2),"",'Supervis@r1'!$C$2) -> ADMINISTRACION | I2: ='Supervis@r1'!$I$2 -> 2025 | J2: ='Supervis@r1'!$J$2 -> 2026
A3: Supervisor/a | C3: =IF(ISBLANK('Supervis@r1'!$C$3),"",CONCATENATE('Supervis@r1'!$C$3," ",'Supervis@r1'!$C$4,",",'Supervis@r1'!$C$5)) -> JEFE JEFE,JOSE
A4: Supervisor/a Intermedio
A6: Puesto evaluado | C6: AUXILIAR ADMINISTRATIVO | F6: DNI | G6: 12345670C | H6: ROL | I6: Colaborador/a
A7: Apellido1 | C7: ALGUIEN
A8: Apellido2 | C8: ALGUIEN
A9: Nombre | C9: MANUEL
A11: ID | B11: Objetivo (Descripción) | C11: Tipo Objetivo (Individual/Colectivo) | D11: Ponderación / Peso Objetivo (%) | E11: Categoría (Número/Porcentaje) | F11: Umbral (nivel de consecución esperado) | G11: Superación (Alza/Baja) | H11: Resultado Alcanzado | I11: Superación Umbral (SÍ/NO) | J11: Puntuación aportada (0 - 100)
A12: =IF(B12="","",COUNTA($B$12:B12)) -> 1 | B12: Realizar al menos 15 horas de formación "no obligatoria" en el periodo a evaluar, con las consideraciones recogidas en el Manual de ED | C12: Individual | D12: 0.2 | E12: Número | F12: 15 | G12: Alza | H12: 15 | I12: =IFERROR(IF(OR(A12="",F12=""),"",IF(AND(G12<>"Alza",G12<>"Baja"),"",IF(G12="Alza",IF(AND(H12<>"",H12>=F12),"SÍ","NO"),IF(G12="Baja",IF(AND(H12<>"",H12<=F12),"SÍ","NO"))))),"") -> SÍ | J12: =IF(B12="","",IFERROR(IF(I12="SÍ",D12*100,0),"")) -> 20
A13: =IF(B13="","",COUNTA($B$12:B13)) -> 2 | B13: Realizar, de forma conjunta por los miembros de la unidad, una propuesta de mejora sobre la actividad que se realiza, en la que se haya indicado los siguientes aspectos "..." En el supuesto de no ser posible/viable realizar la propuesta de forma conjunta, se podrá presentar de forma individual. | C13: Colectivo | D13: 0.2 | E13: Número | F13: 1 | G13: Alza | H13: 1 | I13: =IFERROR(IF(OR(A13="",F13=""),"",IF(AND(G13<>"Alza",G13<>"Baja"),"",IF(G13="Alza",IF(AND(H13<>"",H13>=F13),"SÍ","NO"),IF(G13="Baja",IF(AND(H13<>"",H13<=F13),"SÍ","NO"))))),"") -> SÍ | J13: =IF(B13="","",IFERROR(IF(I13="SÍ",D13*100,0),"")) -> 20
A14: =IF(B14="","",COUNTA($B$12:B14)) -> 3 | B14: Desarrollo de dos conversaciones individuales de feedback al año con las personas bajo tu responsabilidad y/o con tu responsable directo para llevar a cabo una valoración mutua del desarrollo de la actividad. | C14: Individual | D14: 0.2 | E14: Número | F14: 2 | G14: Alza | H14: 2 | I14: =IFERROR(IF(OR(A14="",F14=""),"",IF(AND(G14<>"Alza",G14<>"Baja"),"",IF(G14="Alza",IF(AND(H14<>"",H14>=F14),"SÍ","NO"),IF(G14="Baja",IF(AND(H14<>"",H14<=F14),"SÍ","NO"))))),"") -> SÍ | J14: =IF(B14="","",IFERROR(IF(I14="SÍ",D14*100,0),"")) -> 20
A15: =IF(B15="","",COUNTA($B$12:B15)) -> 4 | B15: Porcentaje de encargos atendidos en la semana en curso | C15: Individual | D15: 0.2 | E15: Porcentaje | F15: 80 | G15: Alza | H15: 100 | I15: =IFERROR(IF(OR(A15="",F15=""),"",IF(AND(G15<>"Alza",G15<>"Baja"),"",IF(G15="Alza",IF(AND(H15<>"",H15>=F15),"SÍ","NO"),IF(G15="Baja",IF(AND(H15<>"",H15<=F15),"SÍ","NO"))))),"") -> SÍ | J15: =IF(B15="","",IFERROR(IF(I15="SÍ",D15*100,0),"")) -> 20
A16: =IF(B16="","",COUNTA($B$12:B16)) -> 5 | B16: Porcentaje de inicidencias gestionadas en la semana en curso | C16: Individual | D16: 0.2 | E16: Porcentaje | F16: 80 | G16: Alza | H16: 100 | I16: =IFERROR(IF(OR(A16="",F16=""),"",IF(AND(G16<>"Alza",G16<>"Baja"),"",IF(G16="Alza",IF(AND(H16<>"",H16>=F16),"SÍ","NO"),IF(G16="Baja",IF(AND(H16<>"",H16<=F16),"SÍ","NO"))))),"") -> SÍ | J16: =IF(B16="","",IFERROR(IF(I16="SÍ",D16*100,0),"")) -> 20
A17: =IF(B17="","",COUNTA($B$12:B17)) | I17: =IFERROR(IF(OR(A17="",F17=""),"",IF(AND(G17<>"Alza",G17<>"Baja"),"",IF(G17="Alza",IF(AND(H17<>"",H17>=F17),"SÍ","NO"),IF(G17="Baja",IF(AND(H17<>"",H17<=F17),"SÍ","NO"))))),"") | J17: =IF(B17="","",IFERROR(IF(I17="SÍ",D17*100,0),""))
A18: =IF(B18="","",COUNTA($B$12:B18)) | I18: =IFERROR(IF(OR(A18="",F18=""),"",IF(AND(G18<>"Alza",G18<>"Baja"),"",IF(G18="Alza",IF(AND(H18<>"",H18>=F18),"SÍ","NO"),IF(G18="Baja",IF(AND(H18<>"",H18<=F18),"SÍ","NO"))))),"") | J18: =IF(B18="","",IFERROR(IF(I18="SÍ",D18*100,0),""))
C19: Total porcentaje asignado | D19: =SUM($D$12:$D$18) -> 1 | I19: Puntuación Final | J19: =IF(D19<>1,0,SUM($J$12:$J$18)) -> 100

Sheet Colaborad@r2
A1: Unidad Organizativa | C1: =IF(ISBLANK('Supervis@r1'!$C$1),"",'Supervis@r1'!$C$1) -> SERVICIOS OPERATIVOS | I1: Periodo Evaluado
A2: Programa | C2: =IF(ISBLANK('Supervis@r1'!$C$2),"",'Supervis@r1'!$C$2) -> ADMINISTRACION | I2: ='Supervis@r1'!$I$2 -> 2025 | J2: ='Supervis@r1'!$J$2 -> 2026
A3: Supervisor/a | C3: =IF(ISBLANK('Supervis@r1'!$C$3),"",CONCATENATE('Supervis@r1'!$C$3," ",'Supervis@r1'!$C$4,",",'Supervis@r1'!$C$5)) -> JEFE JEFE,JOSE
A4: Supervisor/a Intermedio
A6: Puesto evaluado | C6: AUXILIAR ADMINISTRATIVO | F6: DNI | G6: 12345679B | H6: ROL | I6: Colaborador/a
A7: Apellido1 | C7: NADIE
A8: Apellido2 | C8: NADIE
A9: Nombre | C9: MARIA
A11: ID | B11: Objetivo (Descripción) | C11: Tipo Objetivo (Individual/Colectivo) | D11: Ponderación / Peso Objetivo (%) | E11: Categoría (Número/Porcentaje) | F11: Umbral (nivel de consecución esperado) | G11: Superación (Alza/Baja) | H11: Resultado Alcanzado | I11: Superación Umbral (SÍ/NO) | J11: Puntuación aportada (0 - 100)
A12: =IF(B12="","",COUNTA($B$12:B12)) -> 1 | B12: Realizar al menos 15 horas de formación "no obligatoria" en el periodo a evaluar, con las consideraciones recogidas en el Manual de ED | C12: Individual | D12: 0.2 | E12: Número | F12: 15 | G12: Alza | H12: 0 | I12: =IFERROR(IF(OR(A12="",F12=""),"",IF(AND(G12<>"Alza",G12<>"Baja"),"",IF(G12="Alza",IF(AND(H12<>"",H12>=F12),"SÍ","NO"),IF(G12="Baja",IF(AND(H12<>"",H12<=F12),"SÍ","NO"))))),"") -> NO | J12: =IF(B12="","",IFERROR(IF(I12="SÍ",D12*100,0),"")) -> 0
A13: =IF(B13="","",COUNTA($B$12:B13)) -> 2 | B13: Realizar, de forma conjunta por los miembros de la unidad, una propuesta de mejora sobre la actividad que se realiza, en la que se haya indicado los siguientes aspectos "..." En el supuesto de no ser posible/viable realizar la propuesta de forma conjunta, se podrá presentar de forma individual. | C13: Colectivo | D13: 0.2 | E13: Número | F13: 1 | G13: Alza | H13: 0 | I13: =IFERROR(IF(OR(A13="",F13=""),"",IF(AND(G13<>"Alza",G13<>"Baja"),"",IF(G13="Alza",IF(AND(H13<>"",H13>=F13),"SÍ","NO"),IF(G13="Baja",IF(AND(H13<>"",H13<=F13),"SÍ","NO"))))),"") -> NO | J13: =IF(B13="","",IFERROR(IF(I13="SÍ",D13*100,0),"")) -> 0
A14: =IF(B14="","",COUNTA($B$12:B14)) -> 3 | B14: Desarrollo de dos conversaciones individuales de feedback al año con las personas bajo tu responsabilidad y/o con tu responsable directo para llevar a cabo una valoración mutua del desarrollo de la actividad. | C14: Individual | D14: 0.2 | E14: Número | F14: 2 | G14: Alza | H14: 0 | I14: =IFERROR(IF(OR(A14="",F14=""),"",IF(AND(G14<>"Alza",G14<>"Baja"),"",IF(G14="Alza",IF(AND(H14<>"",H14>=F14),"SÍ","NO"),IF(G14="Baja",IF(AND(H14<>"",H14<=F14),"SÍ","NO"))))),"") -> NO | J14: =IF(B14="","",IFERROR(IF(I14="SÍ",D14*100,0),"")) -> 0
A15: =IF(B15="","",COUNTA($B$12:B15)) -> 4 | B15: Porcentaje de encargos atendidos en la semana en curso | C15: Individual | D15: 0.2 | E15: Porcentaje | F15: 80 | G15: Alza | H15: 0 | I15: =IFERROR(IF(OR(A15="",F15=""),"",IF(AND(G15<>"Alza",G15<>"Baja"),"",IF(G15="Alza",IF(AND(H15<>"",H15>=F15),"SÍ","NO"),IF(G15="Baja",IF(AND(H15<>"",H15<=F15),"SÍ","NO"))))),"") -> NO | J15: =IF(B15="","",IFERROR(IF(I15="SÍ",D15*100,0),"")) -> 0
A16: =IF(B16="","",COUNTA($B$12:B16)) -> 5 | B16: Porcentaje de inicidencias gestionadas en la semana en curso | C16: Individual | D16: 0.2 | E16: Porcentaje | F16: 80 | G16: Alza | H16: 0 | I16: =IFERROR(IF(OR(A16="",F16=""),"",IF(AND(G16<>"Alza",G16<>"Baja"),"",IF(G16="Alza",IF(AND(H16<>"",H16>=F16),"SÍ","NO"),IF(G16="Baja",IF(AND(H16<>"",H16<=F16),"SÍ","NO"))))),"") -> NO | J16: =IF(B16="","",IFERROR(IF(I16="SÍ",D16*100,0),"")) -> 0
A17: =IF(B17="","",COUNTA($B$12:B17)) | I17: =IFERROR(IF(OR(A17="",F17=""),"",IF(AND(G17<>"Alza",G17<>"Baja"),"",IF(G17="Alza",IF(AND(H17<>"",H17>=F17),"SÍ","NO"),IF(G17="Baja",IF(AND(H17<>"",H17<=F17),"SÍ","NO"))))),"") | J17: =IF(B17="","",IFERROR(IF(I17="SÍ",D17*100,0),""))
A18: =IF(B18="","",COUNTA($B$12:B18)) | I18: =IFERROR(IF(OR(A18="",F18=""),"",IF(AND(G18<>"Alza",G18<>"Baja"),"",IF(G18="Alza",IF(AND(H18<>"",H18>=F18),"SÍ","NO"),IF(G18="Baja",IF(AND(H18<>"",H18<=F18),"SÍ","NO"))))),"") | J18: =IF(B18="","",IFERROR(IF(I18="SÍ",D18*100,0),""))
C19: Total porcentaje asignado | D19: =SUM($D$12:$D$18) -> 1 | I19: Puntuación Final | J19: =IF(D19<>1,0,SUM($J$12:$J$18)) -> 0

Sheet Colaborad@r3
A1: Unidad Organizativa | C1: =IF(ISBLANK('Supervis@r1'!$C$1),"",'Supervis@r1'!$C$1) -> SERVICIOS OPERATIVOS | I1: Periodo Evaluado
A2: Programa | C2: =IF(ISBLANK('Supervis@r1'!$C$2),"",'Supervis@r1'!$C$2) -> ADMINISTRACION | I2: ='Supervis@r1'!$I$2 -> 2025 | J2: ='Supervis@r1'!$J$2 -> 2026
A3: Supervisor/a | C3: =IF(ISBLANK('Supervis@r1'!$C$3),"",CONCATENATE('Supervis@r1'!$C$3," ",'Supervis@r1'!$C$4,",",'Supervis@r1'!$C$5)) -> JEFE JEFE,JOSE
A4: Supervisor/a Intermedio
A6: Puesto evaluado | C6: AUXILIAR ADMINISTRATIVO | F6: DNI | G6: 12345678A | H6: ROL | I6: Colaborador/a
A7: Apellido1 | C7: EJEMPLO
A8: Apellido2 | C8: EJEMPLO
A9: Nombre | C9: JUAN
A11: ID | B11: Objetivo (Descripción) | C11: Tipo Objetivo (Individual/Colectivo) | D11: Ponderación / Peso Objetivo (%) | E11: Categoría (Número/Porcentaje) | F11: Umbral (nivel de consecución esperado) | G11: Superación (Alza/Baja) | H11: Resultado Alcanzado | I11: Superación Umbral (SÍ/NO) | J11: Puntuación aportada (0 - 100)
A12: =IF(B12="","",COUNTA($B$12:B12)) -> 1 | B12: Realizar al menos 15 horas de formación "no obligatoria" en el periodo a evaluar, con las consideraciones recogidas en el Manual de ED | C12: Individual | D12: 0.2 | E12: Número | F12: 15 | G12: Alza | H12: 60 | I12: =IFERROR(IF(OR(A12="",F12=""),"",IF(AND(G12<>"Alza",G12<>"Baja"),"",IF(G12="Alza",IF(AND(H12<>"",H12>=F12),"SÍ","NO"),IF(G12="Baja",IF(AND(H12<>"",H12<=F12),"SÍ","NO"))))),"") -> SÍ | J12: =IF(B12="","",IFERROR(IF(I12="SÍ",D12*100,0),"")) -> 20
A13: =IF(B13="","",COUNTA($B$12:B13)) -> 2 | B13: Realizar, de forma conjunta por los miembros de la unidad, una propuesta de mejora sobre la actividad que se realiza, en la que se haya indicado los siguientes aspectos "..." En el supuesto de no ser posible/viable realizar la propuesta de forma conjunta, se podrá presentar de forma individual. | C13: Colectivo | D13: 0.2 | E13: Número | F13: 1 | G13: Alza | H13: 1 | I13: =IFERROR(IF(OR(A13="",F13=""),"",IF(AND(G13<>"Alza",G13<>"Baja"),"",IF(G13="Alza",IF(AND(H13<>"",H13>=F13),"SÍ","NO"),IF(G13="Baja",IF(AND(H13<>"",H13<=F13),"SÍ","NO"))))),"") -> SÍ | J13: =IF(B13="","",IFERROR(IF(I13="SÍ",D13*100,0),"")) -> 20
A14: =IF(B14="","",COUNTA($B$12:B14)) -> 3 | B14: Desarrollo de dos conversaciones individuales de feedback al año con las personas bajo tu responsabilidad y/o con tu responsable directo para llevar a cabo una valoración mutua del desarrollo de la actividad. | C14: Individual | D14: 0.2 | E14: Número | F14: 1 | G14: Alza | H14: 1 | I14: =IFERROR(IF(OR(A14="",F14=""),"",IF(AND(G14<>"Alza",G14<>"Baja"),"",IF(G14="Alza",IF(AND(H14<>"",H14>=F14),"SÍ","NO"),IF(G14="Baja",IF(AND(H14<>"",H14<=F14),"SÍ","NO"))))),"") -> SÍ | J14: =IF(B14="","",IFERROR(IF(I14="SÍ",D14*100,0),"")) -> 20
A15: =IF(B15="","",COUNTA($B$12:B15)) -> 4 | B15: Porcentaje de encargos atendidos en la semana en curso | C15: Individual | D15: 0.2 | E15: Porcentaje | F15: 80 | G15: Alza | H15: 100 | I15: =IFERROR(IF(OR(A15="",F15=""),"",IF(AND(G15<>"Alza",G15<>"Baja"),"",IF(G15="Alza",IF(AND(H15<>"",H15>=F15),"SÍ","NO"),IF(G15="Baja",IF(AND(H15<>"",H15<=F15),"SÍ","NO"))))),"") -> SÍ | J15: =IF(B15="","",IFERROR(IF(I15="SÍ",D15*100,0),"")) -> 20
A16: =IF(B16="","",COUNTA($B$12:B16)) -> 5 | B16: Porcentaje de inicidencias gestionadas en la semana en curso | C16: Individual | D16: 0.2 | E16: Porcentaje | F16: 80 | G16: Alza | H16: 100 | I16: =IFERROR(IF(OR(A16="",F16=""),"",IF(AND(G16<>"Alza",G16<>"Baja"),"",IF(G16="Alza",IF(AND(H16<>"",H16>=F16),"SÍ","NO"),IF(G16="Baja",IF(AND(H16<>"",H16<=F16),"SÍ","NO"))))),"") -> SÍ | J16: =IF(B16="","",IFERROR(IF(I16="SÍ",D16*100,0),"")) -> 20
A17: =IF(B17="","",COUNTA($B$12:B17)) | I17: =IFERROR(IF(OR(A17="",F17=""),"",IF(AND(G17<>"Alza",G17<>"Baja"),"",IF(G17="Alza",IF(AND(H17<>"",H17>=F17),"SÍ","NO"),IF(G17="Baja",IF(AND(H17<>"",H17<=F17),"SÍ","NO"))))),"") | J17: =IF(B17="","",IFERROR(IF(I17="SÍ",D17*100,0),""))
A18: =IF(B18="","",COUNTA($B$12:B18)) | I18: =IFERROR(IF(OR(A18="",F18=""),"",IF(AND(G18<>"Alza",G18<>"Baja"),"",IF(G18="Alza",IF(AND(H18<>"",H18>=F18),"SÍ","NO"),IF(G18="Baja",IF(AND(H18<>"",H18<=F18),"SÍ","NO"))))),"") | J18: =IF(B18="","",IFERROR(IF(I18="SÍ",D18*100,0),""))
C19: Total porcentaje asignado | D19: =SUM($D$12:$D$18) -> 1 | I19: Puntuación Final | J19: =IF(D19<>1,0,SUM($J$12:$J$18)) -> 100

Sheet Colaborad@r4
A1: Unidad Organizativa | C1: =IF(ISBLANK('Supervis@r1'!$C$1),"",'Supervis@r1'!$C$1) -> SERVICIOS OPERATIVOS | I1: Periodo Evaluado
A2: Programa | C2: =IF(ISBLANK('Supervis@r1'!$C$2),"",'Supervis@r1'!$C$2) -> ADMINISTRACION | I2: ='Supervis@r1'!$I$2 -> 2025 | J2: ='Supervis@r1'!$J$2 -> 2026
A3: Supervisor/a | C3: =IF(ISBLANK('Supervis@r1'!$C$3),"",CONCATENATE('Supervis@r1'!$C$3," ",'Supervis@r1'!$C$4,",",'Supervis@r1'!$C$5)) -> JEFE JEFE,JOSE
A4: Supervisor/a Intermedio
A6: Puesto evaluado | F6: DNI | H6: ROL | I6: Colaborador/a
A7: Apellido1
A8: Apellido2
A9: Nombre
A11: ID | B11: Objetivo (Descripción) | C11: Tipo Objetivo (Individual/Colectivo) | D11: Ponderación / Peso Objetivo (%) | E11: Categoría (Número/Porcentaje) | F11: Umbral (nivel de consecución esperado) | G11: Superación (Alza/Baja) | H11: Resultado Alcanzado | I11: Superación Umbral (SÍ/NO) | J11: Puntuación aportada (0 - 100)
A12: =IF(B12="","",COUNTA($B$12:B12)) -> 1 | B12: Realizar al menos 15 horas de formación "no obligatoria" en el periodo a evaluar, con las consideraciones recogidas en el Manual de ED | C12: Individual | D12: 0.2 | E12: Número | F12: 15 | G12: Alza | H12: 15 | I12: =IFERROR(IF(OR(A12="",F12=""),"",IF(AND(G12<>"Alza",G12<>"Baja"),"",IF(G12="Alza",IF(AND(H12<>"",H12>=F12),"SÍ","NO"),IF(G12="Baja",IF(AND(H12<>"",H12<=F12),"SÍ","NO"))))),"") -> SÍ | J12: =IF(B12="","",IFERROR(IF(I12="SÍ",D12*100,0),"")) -> 20
A13: =IF(B13="","",COUNTA($B$12:B13)) -> 2 | B13: Realizar, de forma conjunta por los miembros de la unidad, una propuesta de mejora sobre la actividad que se realiza, en la que se haya indicado los siguientes aspectos "..." En el supuesto de no ser posible/viable realizar la propuesta de forma conjunta, se podrá presentar de forma individual. | C13: Colectivo | D13: 0.2 | E13: Número | F13: 1 | G13: Alza | H13: 1 | I13: =IFERROR(IF(OR(A13="",F13=""),"",IF(AND(G13<>"Alza",G13<>"Baja"),"",IF(G13="Alza",IF(AND(H13<>"",H13>=F13),"SÍ","NO"),IF(G13="Baja",IF(AND(H13<>"",H13<=F13),"SÍ","NO"))))),"") -> SÍ | J13: =IF(B13="","",IFERROR(IF(I13="SÍ",D13*100,0),"")) -> 20
A14: =IF(B14="","",COUNTA($B$12:B14)) -> 3 | B14: Desarrollo de dos conversaciones individuales de feedback al año con las personas bajo tu responsabilidad y/o con tu responsable directo para llevar a cabo una valoración mutua del desarrollo de la actividad. | C14: Individual | D14: 0.2 | E14: Número | F14: 2 | G14: Alza | H14: 2 | I14: =IFERROR(IF(OR(A14="",F14=""),"",IF(AND(G14<>"Alza",G14<>"Baja"),"",IF(G14="Alza",IF(AND(H14<>"",H14>=F14),"SÍ","NO"),IF(G14="Baja",IF(AND(H14<>"",H14<=F14),"SÍ","NO"))))),"") -> SÍ | J14: =IF(B14="","",IFERROR(IF(I14="SÍ",D14*100,0),"")) -> 20
A15: =IF(B15="","",COUNTA($B$12:B15)) -> 4 | B15: Porcentaje de encargos atendidos en la semana en curso | C15: Individual | D15: 0.2 | E15: Porcentaje | F15: 80 | G15: Alza | H15: 100 | I15: =IFERROR(IF(OR(A15="",F15=""),"",IF(AND(G15<>"Alza",G15<>"Baja"),"",IF(G15="Alza",IF(AND(H15<>"",H15>=F15),"SÍ","NO"),IF(G15="Baja",IF(AND(H15<>"",H15<=F15),"SÍ","NO"))))),"") -> SÍ | J15: =IF(B15="","",IFERROR(IF(I15="SÍ",D15*100,0),"")) -> 20
A16: =IF(B16="","",COUNTA($B$12:B16)) -> 5 | B16: Porcentaje de inicidencias gestionadas en la semana en curso | C16: Individual | D16: 0.2 | E16: Porcentaje | F16: 80 | G16: Alza | H16: 100 | I16: =IFERROR(IF(OR(A16="",F16=""),"",IF(AND(G16<>"Alza",G16<>"Baja"),"",IF(G16="Alza",IF(AND(H16<>"",H16>=F16),"SÍ","NO"),IF(G16="Baja",IF(AND(H16<>"",H16<=F16),"SÍ","NO"))))),"") -> SÍ | J16: =IF(B16="","",IFERROR(IF(I16="SÍ",D16*100,0),"")) -> 20
A17: =IF(B17="","",COUNTA($B$12:B17)) | I17: =IFERROR(IF(OR(A17="",F17=""),"",IF(AND(G17<>"Alza",G17<>"Baja"),"",IF(G17="Alza",IF(AND(H17<>"",H17>=F17),"SÍ","NO"),IF(G17="Baja",IF(AND(H17<>"",H17<=F17),"SÍ","NO"))))),"") | J17: =IF(B17="","",IFERROR(IF(I17="SÍ",D17*100,0),""))
A18: =IF(B18="","",COUNTA($B$12:B18)) | I18: =IFERROR(IF(OR(A18="",F18=""),"",IF(AND(G18<>"Alza",G18<>"Baja"),"",IF(G18="Alza",IF(AND(H18<>"",H18>=F18),"SÍ","NO"),IF(G18="Baja",IF(AND(H18<>"",H18<=F18),"SÍ","NO"))))),"") | J18: =IF(B18="","",IFERROR(IF(I18="SÍ",D18*100,0),""))
C19: Total porcentaje asignado | D19: =SUM($D$12:$D$18) -> 1 | I19: Puntuación Final | J19: =IF(D19<>1,0,SUM($J$12:$J$18)) -> 100

Sheet Colaborad@r5
A1: Unidad Organizativa | C1: =IF(ISBLANK('Supervis@r1'!$C$1),"",'Supervis@r1'!$C$1) -> SERVICIOS OPERATIVOS | I1: Periodo Evaluado
A2: Programa | C2: =IF(ISBLANK('Supervis@r1'!$C$2),"",'Supervis@r1'!$C$2) -> ADMINISTRACION | I2: ='Supervis@r1'!$I$2 -> 2025 | J2: ='Supervis@r1'!$J$2 -> 2026
A3: Supervisor/a | C3: =IF(ISBLANK('Supervis@r1'!$C$3),"",CONCATENATE('Supervis@r1'!$C$3," ",'Supervis@r1'!$C$4,",",'Supervis@r1'!$C$5)) -> JEFE JEFE,JOSE
A4: Supervisor/a Intermedio
A6: Puesto evaluado | F6: DNI | H6: ROL | I6: Colaborador/a
A7: Apellido1
A8: Apellido2
A9: Nombre
A11: ID | B11: Objetivo (Descripción) | C11: Tipo Objetivo (Individual/Colectivo) | D11: Ponderación / Peso Objetivo (%) | E11: Categoría (Número/Porcentaje) | F11: Umbral (nivel de consecución esperado) | G11: Superación (Alza/Baja) | H11: Resultado Alcanzado | I11: Superación Umbral (SÍ/NO) | J11: Puntuación aportada (0 - 100)
A12: =IF(B12="","",COUNTA($B$12:B12)) -> 1 | B12: Realizar al menos 15 horas de formación "no obligatoria" en el periodo a evaluar, con las consideraciones recogidas en el Manual de ED | C12: Individual | D12: 0.2 | E12: Número | F12: 15 | G12: Alza | I12: =IFERROR(IF(OR(A12="",F12=""),"",IF(AND(G12<>"Alza",G12<>"Baja"),"",IF(G12="Alza",IF(AND(H12<>"",H12>=F12),"SÍ","NO"),IF(G12="Baja",IF(AND(H12<>"",H12<=F12),"SÍ","NO"))))),"") -> NO | J12: =IF(B12="","",IFERROR(IF(I12="SÍ",D12*100,0),"")) -> 0
A13: =IF(B13="","",COUNTA($B$12:B13)) -> 2 | B13: Realizar, de forma conjunta por los miembros de la unidad, una propuesta de mejora sobre la actividad que se realiza, en la que se haya indicado los siguientes aspectos "..." En el supuesto de no ser posible/viable realizar la propuesta de forma conjunta, se podrá presentar de forma individual. | C13: Colectivo | D13: 0.2 | E13: Número | F13: 1 | G13: Alza | I13: =IFERROR(IF(OR(A13="",F13=""),"",IF(AND(G13<>"Alza",G13<>"Baja"),"",IF(G13="Alza",IF(AND(H13<>"",H13>=F13),"SÍ","NO"),IF(G13="Baja",IF(AND(H13<>"",H13<=F13),"SÍ","NO"))))),"") -> NO | J13: =IF(B13="","",IFERROR(IF(I13="SÍ",D13*100,0),"")) -> 0
A14: =IF(B14="","",COUNTA($B$12:B14)) -> 3 | B14: Desarrollo de dos conversaciones individuales de feedback al año con las personas bajo tu responsabilidad y/o con tu responsable directo para llevar a cabo una valoración mutua del desarrollo de la actividad. | C14: Individual | D14: 0.2 | E14: Número | F14: 2 | G14: Alza | I14: =IFERROR(IF(OR(A14="",F14=""),"",IF(AND(G14<>"Alza",G14<>"Baja"),"",IF(G14="Alza",IF(AND(H14<>"",H14>=F14),"SÍ","NO"),IF(G14="Baja",IF(AND(H14<>"",H14<=F14),"SÍ","NO"))))),"") -> NO | J14: =IF(B14="","",IFERROR(IF(I14="SÍ",D14*100,0),"")) -> 0
A15: =IF(B15="","",COUNTA($B$12:B15)) | I15: =IFERROR(IF(OR(A15="",F15=""),"",IF(AND(G15<>"Alza",G15<>"Baja"),"",IF(G15="Alza",IF(AND(H15<>"",H15>=F15),"SÍ","NO"),IF(G15="Baja",IF(AND(H15<>"",H15<=F15),"SÍ","NO"))))),"") | J15: =IF(B15="","",IFERROR(IF(I15="SÍ",D15*100,0),""))
A16: =IF(B16="","",COUNTA($B$12:B16)) | I16: =IFERROR(IF(OR(A16="",F16=""),"",IF(AND(G16<>"Alza",G16<>"Baja"),"",IF(G16="Alza",IF(AND(H16<>"",H16>=F16),"SÍ","NO"),IF(G16="Baja",IF(AND(H16<>"",H16<=F16),"SÍ","NO"))))),"") | J16: =IF(B16="","",IFERROR(IF(I16="SÍ",D16*100,0),""))
A17: =IF(B17="","",COUNTA($B$12:B17)) | I17: =IFERROR(IF(OR(A17="",F17=""),"",IF(AND(G17<>"Alza",G17<>"Baja"),"",IF(G17="Alza",IF(AND(H17<>"",H17>=F17),"SÍ","NO"),IF(G17="Baja",IF(AND(H17<>"",H17<=F17),"SÍ","NO"))))),"") | J17: =IF(B17="","",IFERROR(IF(I17="SÍ",D17*100,0),""))
A18: =IF(B18="","",COUNTA($B$12:B18)) | I18: =IFERROR(IF(OR(A18="",F18=""),"",IF(AND(G18<>"Alza",G18<>"Baja"),"",IF(G18="Alza",IF(AND(H18<>"",H18>=F18),"SÍ","NO"),IF(G18="Baja",IF(AND(H18<>"",H18<=F18),"SÍ","NO"))))),"") | J18: =IF(B18="","",IFERROR(IF(I18="SÍ",D18*100,0),""))
C19: Total porcentaje asignado | D19: =SUM($D$12:$D$18) -> 0.6 | I19: Puntuación Final | J19: =IF(D19<>1,0,SUM($J$12:$J$18)) -> 0

Sheet Colaborad@r6
A1: Unidad Organizativa | C1: =IF(ISBLANK('Supervis@r1'!$C$1),"",'Supervis@r1'!$C$1) -> SERVICIOS OPERATIVOS | I1: Periodo Evaluado
A2: Programa | C2: =IF(ISBLANK('Supervis@r1'!$C$2),"",'Supervis@r1'!$C$2) -> ADMINISTRACION | I2: ='Supervis@r1'!$I$2 -> 2025 | J2: ='Supervis@r1'!$J$2 -> 2026
A3: Supervisor/a | C3: =IF(ISBLANK('Supervis@r1'!$C$3),"",CONCATENATE('Supervis@r1'!$C$3," ",'Supervis@r1'!$C$4,",",'Supervis@r1'!$C$5)) -> JEFE JEFE,JOSE
A4: Supervisor/a Intermedio
A6: Puesto evaluado | F6: DNI | H6: ROL | I6: Colaborador/a
A7: Apellido1
A8: Apellido2
A9: Nombre
A11: ID | B11: Objetivo (Descripción) | C11: Tipo Objetivo (Individual/Colectivo) | D11: Ponderación / Peso Objetivo (%) | E11: Categoría (Número/Porcentaje) | F11: Umbral (nivel de consecución esperado) | G11: Superación (Alza/Baja) | H11: Resultado Alcanzado | I11: Superación Umbral (SÍ/NO) | J11: Puntuación aportada (0 - 100)
A12: =IF(B12="","",COUNTA($B$12:B12)) -> 1 | B12: Realizar al menos 15 horas de formación "no obligatoria" en el periodo a evaluar, con las consideraciones recogidas en el Manual de ED | C12: Individual | D12: 0.2 | E12: Número | F12: 15 | G12: Alza | I12: =IFERROR(IF(OR(A12="",F12=""),"",IF(AND(G12<>"Alza",G12<>"Baja"),"",IF(G12="Alza",IF(AND(H12<>"",H12>=F12),"SÍ","NO"),IF(G12="Baja",IF(AND(H12<>"",H12<=F12),"SÍ","NO"))))),"") -> NO | J12: =IF(B12="","",IFERROR(IF(I12="SÍ",D12*100,0),"")) -> 0
A13: =IF(B13="","",COUNTA($B$12:B13)) -> 2 | B13: Realizar, de forma conjunta por los miembros de la unidad, una propuesta de mejora sobre la actividad que se realiza, en la que se haya indicado los siguientes aspectos "..." En el supuesto de no ser posible/viable realizar la propuesta de forma conjunta, se podrá presentar de forma individual. | C13: Colectivo | D13: 0.2 | E13: Número | F13: 1 | G13: Alza | I13: =IFERROR(IF(OR(A13="",F13=""),"",IF(AND(G13<>"Alza",G13<>"Baja"),"",IF(G13="Alza",IF(AND(H13<>"",H13>=F13),"SÍ","NO"),IF(G13="Baja",IF(AND(H13<>"",H13<=F13),"SÍ","NO"))))),"") -> NO | J13: =IF(B13="","",IFERROR(IF(I13="SÍ",D13*100,0),"")) -> 0
A14: =IF(B14="","",COUNTA($B$12:B14)) -> 3 | B14: Desarrollo de dos conversaciones individuales de feedback al año con las personas bajo tu responsabilidad y/o con tu responsable directo para llevar a cabo una valoración mutua del desarrollo de la actividad. | C14: Individual | D14: 0.2 | E14: Número | F14: 2 | G14: Alza | I14: =IFERROR(IF(OR(A14="",F14=""),"",IF(AND(G14<>"Alza",G14<>"Baja"),"",IF(G14="Alza",IF(AND(H14<>"",H14>=F14),"SÍ","NO"),IF(G14="Baja",IF(AND(H14<>"",H14<=F14),"SÍ","NO"))))),"") -> NO | J14: =IF(B14="","",IFERROR(IF(I14="SÍ",D14*100,0),"")) -> 0
A15: =IF(B15="","",COUNTA($B$12:B15)) | I15: =IFERROR(IF(OR(A15="",F15=""),"",IF(AND(G15<>"Alza",G15<>"Baja"),"",IF(G15="Alza",IF(AND(H15<>"",H15>=F15),"SÍ","NO"),IF(G15="Baja",IF(AND(H15<>"",H15<=F15),"SÍ","NO"))))),"") | J15: =IF(B15="","",IFERROR(IF(I15="SÍ",D15*100,0),""))
A16: =IF(B16="","",COUNTA($B$12:B16)) | I16: =IFERROR(IF(OR(A16="",F16=""),"",IF(AND(G16<>"Alza",G16<>"Baja"),"",IF(G16="Alza",IF(AND(H16<>"",H16>=F16),"SÍ","NO"),IF(G16="Baja",IF(AND(H16<>"",H16<=F16),"SÍ","NO"))))),"") | J16: =IF(B16="","",IFERROR(IF(I16="SÍ",D16*100,0),""))
A17: =IF(B17="","",COUNTA($B$12:B17)) | I17: =IFERROR(IF(OR(A17="",F17=""),"",IF(AND(G17<>"Alza",G17<>"Baja"),"",IF(G17="Alza",IF(AND(H17<>"",H17>=F17),"SÍ","NO"),IF(G17="Baja",IF(AND(H17<>"",H17<=F17),"SÍ","NO"))))),"") | J17: =IF(B17="","",IFERROR(IF(I17="SÍ",D17*100,0),""))
A18: =IF(B18="","",COUNTA($B$12:B18)) | I18: =IFERROR(IF(OR(A18="",F18=""),"",IF(AND(G18<>"Alza",G18<>"Baja"),"",IF(G18="Alza",IF(AND(H18<>"",H18>=F18),"SÍ","NO"),IF(G18="Baja",IF(AND(H18<>"",H18<=F18),"SÍ","NO"))))),"") | J18: =IF(B18="","",IFERROR(IF(I18="SÍ",D18*100,0),""))
C19: Total porcentaje asignado | D19: =SUM($D$12:$D$18) -> 0.6 | I19: Puntuación Final | J19: =IF(D19<>1,0,SUM($J$12:$J$18)) -> 0

Sheet Colaborad@r7
A1: Unidad Organizativa | C1: =IF(ISBLANK('Supervis@r1'!$C$1),"",'Supervis@r1'!$C$1) -> SERVICIOS OPERATIVOS | I1: Periodo Evaluado
A2: Programa | C2: =IF(ISBLANK('Supervis@r1'!$C$2),"",'Supervis@r1'!$C$2) -> ADMINISTRACION | I2: ='Supervis@r1'!$I$2 -> 2025 | J2: ='Supervis@r1'!$J$2 -> 2026
A3: Supervisor/a | C3: =IF(ISBLANK('Supervis@r1'!$C$3),"",CONCATENATE('Supervis@r1'!$C$3," ",'Supervis@r1'!$C$4,",",'Supervis@r1'!$C$5)) -> JEFE JEFE,JOSE
A4: Supervisor/a Intermedio
A6: Puesto evaluado | F6: DNI | H6: ROL | I6: Colaborador/a
A7: Apellido1
A8: Apellido2
A9: Nombre
A11: ID | B11: Objetivo (Descripción) | C11: Tipo Objetivo (Individual/Colectivo) | D11: Ponderación / Peso Objetivo (%) | E11: Categoría (Número/Porcentaje) | F11: Umbral (nivel de consecución esperado) | G11: Superación (Alza/Baja) | H11: Resultado Alcanzado | I11: Superación Umbral (SÍ/NO) | J11: Puntuación aportada (0 - 100)
A12: =IF(B12="","",COUNTA($B$12:B12)) -> 1 | B12: Realizar al menos 15 horas de formación "no obligatoria" en el periodo a evaluar, con las consideraciones recogidas en el Manual de ED | C12: Individual | D12: 0.2 | E12: Número | F12: 15 | G12: Alza | I12: =IFERROR(IF(OR(A12="",F12=""),"",IF(AND(G12<>"Alza",G12<>"Baja"),"",IF(G12="Alza",IF(AND(H12<>"",H12>=F12),"SÍ","NO"),IF(G12="Baja",IF(AND(H12<>"",H12<=F12),"SÍ","NO"))))),"") -> NO | J12: =IF(B12="","",IFERROR(IF(I12="SÍ",D12*100,0),"")) -> 0
A13: =IF(B13="","",COUNTA($B$12:B13)) -> 2 | B13: Realizar, de forma conjunta por los miembros de la unidad, una propuesta de mejora sobre la actividad que se realiza, en la que se haya indicado los siguientes aspectos "..." En el supuesto de no ser posible/viable realizar la propuesta de forma conjunta, se podrá presentar de forma individual. | C13: Colectivo | D13: 0.2 | E13: Número | F13: 1 | G13: Alza | I13: =IFERROR(IF(OR(A13="",F13=""),"",IF(AND(G13<>"Alza",G13<>"Baja"),"",IF(G13="Alza",IF(AND(H13<>"",H13>=F13),"SÍ","NO"),IF(G13="Baja",IF(AND(H13<>"",H13<=F13),"SÍ","NO"))))),"") -> NO | J13: =IF(B13="","",IFERROR(IF(I13="SÍ",D13*100,0),"")) -> 0
A14: =IF(B14="","",COUNTA($B$12:B14)) -> 3 | B14: Desarrollo de dos conversaciones individuales de feedback al año con las personas bajo tu responsabilidad y/o con tu responsable directo para llevar a cabo una valoración mutua del desarrollo de la actividad. | C14: Individual | D14: 0.2 | E14: Número | F14: 2 | G14: Alza | I14: =IFERROR(IF(OR(A14="",F14=""),"",IF(AND(G14<>"Alza",G14<>"Baja"),"",IF(G14="Alza",IF(AND(H14<>"",H14>=F14),"SÍ","NO"),IF(G14="Baja",IF(AND(H14<>"",H14<=F14),"SÍ","NO"))))),"") -> NO | J14: =IF(B14="","",IFERROR(IF(I14="SÍ",D14*100,0),"")) -> 0
A15: =IF(B15="","",COUNTA($B$12:B15)) | I15: =IFERROR(IF(OR(A15="",F15=""),"",IF(AND(G15<>"Alza",G15<>"Baja"),"",IF(G15="Alza",IF(AND(H15<>"",H15>=F15),"SÍ","NO"),IF(G15="Baja",IF(AND(H15<>"",H15<=F15),"SÍ","NO"))))),"") | J15: =IF(B15="","",IFERROR(IF(I15="SÍ",D15*100,0),""))
A16: =IF(B16="","",COUNTA($B$12:B16)) | I16: =IFERROR(IF(OR(A16="",F16=""),"",IF(AND(G16<>"Alza",G16<>"Baja"),"",IF(G16="Alza",IF(AND(H16<>"",H16>=F16),"SÍ","NO"),IF(G16="Baja",IF(AND(H16<>"",H16<=F16),"SÍ","NO"))))),"") | J16: =IF(B16="","",IFERROR(IF(I16="SÍ",D16*100,0),""))
A17: =IF(B17="","",COUNTA($B$12:B17)) | I17: =IFERROR(IF(OR(A17="",F17=""),"",IF(AND(G17<>"Alza",G17<>"Baja"),"",IF(G17="Alza",IF(AND(H17<>"",H17>=F17),"SÍ","NO"),IF(G17="Baja",IF(AND(H17<>"",H17<=F17),"SÍ","NO"))))),"") | J17: =IF(B17="","",IFERROR(IF(I17="SÍ",D17*100,0),""))
A18: =IF(B18="","",COUNTA($B$12:B18)) | I18: =IFERROR(IF(OR(A18="",F18=""),"",IF(AND(G18<>"Alza",G18<>"Baja"),"",IF(G18="Alza",IF(AND(H18<>"",H18>=F18),"SÍ","NO"),IF(G18="Baja",IF(AND(H18<>"",H18<=F18),"SÍ","NO"))))),"") | J18: =IF(B18="","",IFERROR(IF(I18="SÍ",D18*100,0),""))
C19: Total porcentaje asignado | D19: =SUM($D$12:$D$18) -> 0.6 | I19: Puntuación Final | J19: =IF(D19<>1,0,SUM($J$12:$J$18)) -> 0

Sheet Colaborad@r8
A1: Unidad Organizativa | C1: =IF(ISBLANK('Supervis@r1'!$C$1),"",'Supervis@r1'!$C$1) -> SERVICIOS OPERATIVOS | I1: Periodo Evaluado
A2: Programa | C2: =IF(ISBLANK('Supervis@r1'!$C$2),"",'Supervis@r1'!$C$2) -> ADMINISTRACION | I2: ='Supervis@r1'!$I$2 -> 2025 | J2: ='Supervis@r1'!$J$2 -> 2026
A3: Supervisor/a | C3: =IF(ISBLANK('Supervis@r1'!$C$3),"",CONCATENATE('Supervis@r1'!$C$3," ",'Supervis@r1'!$C$4,",",'Supervis@r1'!$C$5)) -> JEFE JEFE,JOSE
A4: Supervisor/a Intermedio
A6: Puesto evaluado | F6: DNI | H6: ROL | I6: Colaborador/a
A7: Apellido1
A8: Apellido2
A9: Nombre
A11: ID | B11: Objetivo (Descripción) | C11: Tipo Objetivo (Individual/Colectivo) | D11: Ponderación / Peso Objetivo (%) | E11: Categoría (Número/Porcentaje) | F11: Umbral (nivel de consecución esperado) | G11: Superación (Alza/Baja) | H11: Resultado Alcanzado | I11: Superación Umbral (SÍ/NO) | J11: Puntuación aportada (0 - 100)
A12: =IF(B12="","",COUNTA($B$12:B12)) -> 1 | B12: Realizar al menos 15 horas de formación "no obligatoria" en el periodo a evaluar, con las consideraciones recogidas en el Manual de ED | C12: Individual | D12: 0.2 | E12: Número | F12: 15 | G12: Alza | I12: =IFERROR(IF(OR(A12="",F12=""),"",IF(AND(G12<>"Alza",G12<>"Baja"),"",IF(G12="Alza",IF(AND(H12<>"",H12>=F12),"SÍ","NO"),IF(G12="Baja",IF(AND(H12<>"",H12<=F12),"SÍ","NO"))))),"") -> NO | J12: =IF(B12="","",IFERROR(IF(I12="SÍ",D12*100,0),"")) -> 0
A13: =IF(B13="","",COUNTA($B$12:B13)) -> 2 | B13: Realizar, de forma conjunta por los miembros de la unidad, una propuesta de mejora sobre la actividad que se realiza, en la que se haya indicado los siguientes aspectos "..." En el supuesto de no ser posible/viable realizar la propuesta de forma conjunta, se podrá presentar de forma individual. | C13: Colectivo | D13: 0.2 | E13: Número | F13: 1 | G13: Alza | I13: =IFERROR(IF(OR(A13="",F13=""),"",IF(AND(G13<>"Alza",G13<>"Baja"),"",IF(G13="Alza",IF(AND(H13<>"",H13>=F13),"SÍ","NO"),IF(G13="Baja",IF(AND(H13<>"",H13<=F13),"SÍ","NO"))))),"") -> NO | J13: =IF(B13="","",IFERROR(IF(I13="SÍ",D13*100,0),"")) -> 0
A14: =IF(B14="","",COUNTA($B$12:B14)) -> 3 | B14: Desarrollo de dos conversaciones individuales de feedback al año con las personas bajo tu responsabilidad y/o con tu responsable directo para llevar a cabo una valoración mutua del desarrollo de la actividad. | C14: Individual | D14: 0.2 | E14: Número | F14: 2 | G14: Alza | I14: =IFERROR(IF(OR(A14="",F14=""),"",IF(AND(G14<>"Alza",G14<>"Baja"),"",IF(G14="Alza",IF(AND(H14<>"",H14>=F14),"SÍ","NO"),IF(G14="Baja",IF(AND(H14<>"",H14<=F14),"SÍ","NO"))))),"") -> NO | J14: =IF(B14="","",IFERROR(IF(I14="SÍ",D14*100,0),"")) -> 0
A15: =IF(B15="","",COUNTA($B$12:B15)) | I15: =IFERROR(IF(OR(A15="",F15=""),"",IF(AND(G15<>"Alza",G15<>"Baja"),"",IF(G15="Alza",IF(AND(H15<>"",H15>=F15),"SÍ","NO"),IF(G15="Baja",IF(AND(H15<>"",H15<=F15),"SÍ","NO"))))),"") | J15: =IF(B15="","",IFERROR(IF(I15="SÍ",D15*100,0),""))
A16: =IF(B16="","",COUNTA($B$12:B16)) | I16: =IFERROR(IF(OR(A16="",F16=""),"",IF(AND(G16<>"Alza",G16<>"Baja"),"",IF(G16="Alza",IF(AND(H16<>"",H16>=F16),"SÍ","NO"),IF(G16="Baja",IF(AND(H16<>"",H16<=F16),"SÍ","NO"))))),"") | J16: =IF(B16="","",IFERROR(IF(I16="SÍ",D16*100,0),""))
A17: =IF(B17="","",COUNTA($B$12:B17)) | I17: =IFERROR(IF(OR(A17="",F17=""),"",IF(AND(G17<>"Alza",G17<>"Baja"),"",IF(G17="Alza",IF(AND(H17<>"",H17>=F17),"SÍ","NO"),IF(G17="Baja",IF(AND(H17<>"",H17<=F17),"SÍ","NO"))))),"") | J17: =IF(B17="","",IFERROR(IF(I17="SÍ",D17*100,0),""))
A18: =IF(B18="","",COUNTA($B$12:B18)) | I18: =IFERROR(IF(OR(A18="",F18=""),"",IF(AND(G18<>"Alza",G18<>"Baja"),"",IF(G18="Alza",IF(AND(H18<>"",H18>=F18),"SÍ","NO"),IF(G18="Baja",IF(AND(H18<>"",H18<=F18),"SÍ","NO"))))),"") | J18: =IF(B18="","",IFERROR(IF(I18="SÍ",D18*100,0),""))
C19: Total porcentaje asignado | D19: =SUM($D$12:$D$18) -> 0.6 | I19: Puntuación Final | J19: =IF(D19<>1,0,SUM($J$12:$J$18)) -> 0

Sheet Colaborad@r9
A1: Unidad Organizativa | C1: =IF(ISBLANK('Supervis@r1'!$C$1),"",'Supervis@r1'!$C$1) -> SERVICIOS OPERATIVOS | I1: Periodo Evaluado
A2: Programa | C2: =IF(ISBLANK('Supervis@r1'!$C$2),"",'Supervis@r1'!$C$2) -> ADMINISTRACION | I2: ='Supervis@r1'!$I$2 -> 2025 | J2: ='Supervis@r1'!$J$2 -> 2026
A3: Supervisor/a | C3: =IF(ISBLANK('Supervis@r1'!$C$3),"",CONCATENATE('Supervis@r1'!$C$3," ",'Supervis@r1'!$C$4,",",'Supervis@r1'!$C$5)) -> JEFE JEFE,JOSE
A4: Supervisor/a Intermedio
A6: Puesto evaluado | F6: DNI | H6: ROL | I6: Colaborador/a
A7: Apellido1
A8: Apellido2
A9: Nombre
A11: ID | B11: Objetivo (Descripción) | C11: Tipo Objetivo (Individual/Colectivo) | D11: Ponderación / Peso Objetivo (%) | E11: Categoría (Número/Porcentaje) | F11: Umbral (nivel de consecución esperado) | G11: Superación (Alza/Baja) | H11: Resultado Alcanzado | I11: Superación Umbral (SÍ/NO) | J11: Puntuación aportada (0 - 100)
